Workbook
Name Antall_uker_i_turnus_1_8_dropdown: #REF!
Name Ja_og_nei: #REF!
Name kost: #REF!
Name Ukedager: #REF!
Name UkeSatsTimer: #REF!

Sheet Vaktplan
A1: Turnus Planlegger | L1: This Workbook was created by Tom Erik Revheim. T.e.revheim@hotmail.com | M1: Dokumentets eies av tom Erik Revheim
A2: Uke: | C2: 1 | H2: Uke: | J2: 2 | O2: Uke: | Q2: 3 | V2: Uke: | X2: 4 | AC2: Uke: | AE2: 5 | AJ2: Uke: | AL2: 6 | AQ2: Uke: | AS2: 7 | AX2: Uke: | AZ2: 8 | BE2: Uke: | BG2: 9 | BL2: Uke: | BN2: 10 | BS2: Uke: | BU2: 11 | BZ2: Uke: | CB2: 12
A3: =IF($G$38="Mandag","m",IF($G$38="Tirsdag","t",IF($G$38="Onsdag","o",IF($G$38="Torsdag","t",IF($G$38="Fredag","f",IF($G$38="Lørdag","l",IF($G$38="Søndag","s","N/A"))))))) -> m | B3: =IF($G$38="Mandag","t",IF($G$38="Tirsdag","o",IF($G$38="Onsdag","t",IF($G$38="Torsdag","f",IF($G$38="Fredag","l",IF($G$38="Lørdag","s",IF($G$38="Søndag","m","N/A"))))))) -> t | C3: =IF($G$38="Mandag","o",IF($G$38="Tirsdag","t",IF($G$38="Onsdag","f",IF($G$38="Torsdag","l",IF($G$38="Fredag","s",IF($G$38="Lørdag","m",IF($G$38="Søndag","t","N/A"))))))) -> o | D3: =IF($G$38="Mandag","t",IF($G$38="Tirsdag","f",IF($G$38="Onsdag","l",IF($G$38="Torsdag","s",IF($G$38="Fredag","m",IF($G$38="Lørdag","t",IF($G$38="Søndag","o","N/A"))))))) -> t | E3: =IF($G$38="Mandag","f",IF($G$38="Tirsdag","l",IF($G$38="Onsdag","s",IF($G$38="Torsdag","m",IF($G$38="Fredag","t",IF($G$38="Lørdag","o",IF($G$38="Søndag","t","N/A"))))))) -> f | F3: =IF($G$38="Mandag","l",IF($G$38="Tirsdag","s",IF($G$38="Onsdag","m",IF($G$38="Torsdag","t",IF($G$38="Fredag","o",IF($G$38="Lørdag","t",IF($G$38="Søndag","f","N/A"))))))) -> l | G3: =IF($G$38="Mandag","s",IF($G$38="Tirsdag","m",IF($G$38="Onsdag","t",IF($G$38="Torsdag","o",IF($G$38="Fredag","t",IF($G$38="Lørdag","f",IF($G$38="Søndag","l","N/A"))))))) -> s | H3: =IF($G$38="Mandag","m",IF($G$38="Tirsdag","t",IF($G$38="Onsdag","o",IF($G$38="Torsdag","t",IF($G$38="Fredag","f",IF($G$38="Lørdag","l",IF($G$38="Søndag","s","N/A"))))))) -> m | I3: =IF($G$38="Mandag","t",IF($G$38="Tirsdag","o",IF($G$38="Onsdag","t",IF($G$38="Torsdag","f",IF($G$38="Fredag","l",IF($G$38="Lørdag","s",IF($G$38="Søndag","m","N/A"))))))) -> t | J3: =IF($G$38="Mandag","o",IF($G$38="Tirsdag","t",IF($G$38="Onsdag","f",IF($G$38="Torsdag","l",IF($G$38="Fredag","s",IF($G$38="Lørdag","m",IF($G$38="Søndag","t","N/A"))))))) -> o | K3: =IF($G$38="Mandag","t",IF($G$38="Tirsdag","f",IF($G$38="Onsdag","l",IF($G$38="Torsdag","s",IF($G$38="Fredag","m",IF($G$38="Lørdag","t",IF($G$38="Søndag","o","N/A"))))))) -> t | L3: =IF($G$38="Mandag","f",IF($G$38="Tirsdag","l",IF($G$38="Onsdag","s",IF($G$38="Torsdag","m",IF($G$38="Fredag","t",IF($G$38="Lørdag","o",IF($G$38="Søndag","t","N/A"))))))) -> f | M3: =IF($G$38="Mandag","l",IF($G$38="Tirsdag","s",IF($G$38="Onsdag","m",IF($G$38="Torsdag","t",IF($G$38="Fredag","o",IF($G$38="Lørdag","t",IF($G$38="Søndag","f","N/A"))))))) -> l | N3: =IF($G$38="Mandag","s",IF($G$38="Tirsdag","m",IF($G$38="Onsdag","t",IF($G$38="Torsdag","o",IF($G$38="Fredag","t",IF($G$38="Lørdag","f",IF($G$38="Søndag","l","N/A"))))))) -> s | O3: =IF($G$38="Mandag","m",IF($G$38="Tirsdag","t",IF($G$38="Onsdag","o",IF($G$38="Torsdag","t",IF($G$38="Fredag","f",IF($G$38="Lørdag","l",IF($G$38="Søndag","s","N/A"))))))) -> m | P3: =IF($G$38="Mandag","t",IF($G$38="Tirsdag","o",IF($G$38="Onsdag","t",IF($G$38="Torsdag","f",IF($G$38="Fredag","l",IF($G$38="Lørdag","s",IF($G$38="Søndag","m","N/A"))))))) -> t | Q3: =IF($G$38="Mandag","o",IF($G$38="Tirsdag","t",IF($G$38="Onsdag","f",IF($G$38="Torsdag","l",IF($G$38="Fredag","s",IF($G$38="Lørdag","m",IF($G$38="Søndag","t","N/A"))))))) -> o | R3: =IF($G$38="Mandag","t",IF($G$38="Tirsdag","f",IF($G$38="Onsdag","l",IF($G$38="Torsdag","s",IF($G$38="Fredag","m",IF($G$38="Lørdag","t",IF($G$38="Søndag","o","N/A"))))))) -> t | S3: =IF($G$38="Mandag","f",IF($G$38="Tirsdag","l",IF($G$38="Onsdag","s",IF($G$38="Torsdag","m",IF($G$38="Fredag","t",IF($G$38="Lørdag","o",IF($G$38="Søndag","t","N/A"))))))) -> f | T3: =IF($G$38="Mandag","l",IF($G$38="Tirsdag","s",IF($G$38="Onsdag","m",IF($G$38="Torsdag","t",IF($G$38="Fredag","o",IF($G$38="Lørdag","t",IF($G$38="Søndag","f","N/A"))))))) -> l | U3: =IF($G$38="Mandag","s",IF($G$38="Tirsdag","m",IF($G$38="Onsdag","t",IF($G$38="Torsdag","o",IF($G$38="Fredag","t",IF($G$38="Lørdag","f",IF($G$38="Søndag","l","N/A"))))))) -> s | V3: =IF($G$38="Mandag","m",IF($G$38="Tirsdag","t",IF($G$38="Onsdag","o",IF($G$38="Torsdag","t",IF($G$38="Fredag","f",IF($G$38="Lørdag","l",IF($G$38="Søndag","s","N/A"))))))) -> m | W3: =IF($G$38="Mandag","t",IF($G$38="Tirsdag","o",IF($G$38="Onsdag","t",IF($G$38="Torsdag","f",IF($G$38="Fredag","l",IF($G$38="Lørdag","s",IF($G$38="Søndag","m","N/A"))))))) -> t | X3: =IF($G$38="Mandag","o",IF($G$38="Tirsdag","t",IF($G$38="Onsdag","f",IF($G$38="Torsdag","l",IF($G$38="Fredag","s",IF($G$38="Lørdag","m",IF($G$38="Søndag","t","N/A"))))))) -> o | Y3: =IF($G$38="Mandag","t",IF($G$38="Tirsdag","f",IF($G$38="Onsdag","l",IF($G$38="Torsdag","s",IF($G$38="Fredag","m",IF($G$38="Lørdag","t",IF($G$38="Søndag","o","N/A"))))))) -> t | Z3: =IF($G$38="Mandag","f",IF($G$38="Tirsdag","l",IF($G$38="Onsdag","s",IF($G$38="Torsdag","m",IF($G$38="Fredag","t",IF($G$38="Lørdag","o",IF($G$38="Søndag","t","N/A"))))))) -> f | AA3: =IF($G$38="Mandag","l",IF($G$38="Tirsdag","s",IF($G$38="Onsdag","m",IF($G$38="Torsdag","t",IF($G$38="Fredag","o",IF($G$38="Lørdag","t",IF($G$38="Søndag","f","N/A"))))))) -> l | AB3: =IF($G$38="Mandag","s",IF($G$38="Tirsdag","m",IF($G$38="Onsdag","t",IF($G$38="Torsdag","o",IF($G$38="Fredag","t",IF($G$38="Lørdag","f",IF($G$38="Søndag","l","N/A"))))))) -> s | AC3: =IF($G$38="Mandag","m",IF($G$38="Tirsdag","t",IF($G$38="Onsdag","o",IF($G$38="Torsdag","t",IF($G$38="Fredag","f",IF($G$38="Lørdag","l",IF($G$38="Søndag","s","N/A"))))))) -> m | AD3: =IF($G$38="Mandag","t",IF($G$38="Tirsdag","o",IF($G$38="Onsdag","t",IF($G$38="Torsdag","f",IF($G$38="Fredag","l",IF($G$38="Lørdag","s",IF($G$38="Søndag","m","N/A"))))))) -> t | AE3: =IF($G$38="Mandag","o",IF($G$38="Tirsdag","t",IF($G$38="Onsdag","f",IF($G$38="Torsdag","l",IF($G$38="Fredag","s",IF($G$38="Lørdag","m",IF($G$38="Søndag","t","N/A"))))))) -> o | AF3: =IF($G$38="Mandag","t",IF($G$38="Tirsdag","f",IF($G$38="Onsdag","l",IF($G$38="Torsdag","s",IF($G$38="Fredag","m",IF($G$38="Lørdag","t",IF($G$38="Søndag","o","N/A"))))))) -> t | AG3: =IF($G$38="Mandag","f",IF($G$38="Tirsdag","l",IF($G$38="Onsdag","s",IF($G$38="Torsdag","m",IF($G$38="Fredag","t",IF($G$38="Lørdag","o",IF($G$38="Søndag","t","N/A"))))))) -> f | AH3: =IF($G$38="Mandag","l",IF($G$38="Tirsdag","s",IF($G$38="Onsdag","m",IF($G$38="Torsdag","t",IF($G$38="Fredag","o",IF($G$38="Lørdag","t",IF($G$38="Søndag","f","N/A"))))))) -> l | AI3: =IF($G$38="Mandag","s",IF($G$38="Tirsdag","m",IF($G$38="Onsdag","t",IF($G$38="Torsdag","o",IF($G$38="Fredag","t",IF($G$38="Lørdag","f",IF($G$38="Søndag","l","N/A"))))))) -> s | AJ3: =IF($G$38="Mandag","m",IF($G$38="Tirsdag","t",IF($G$38="Onsdag","o",IF($G$38="Torsdag","t",IF($G$38="Fredag","f",IF($G$38="Lørdag","l",IF($G$38="Søndag","s","N/A"))))))) -> m | AK3: =IF($G$38="Mandag","t",IF($G$38="Tirsdag","o",IF($G$38="Onsdag","t",IF($G$38="Torsdag","f",IF($G$38="Fredag","l",IF($G$38="Lørdag","s",IF($G$38="Søndag","m","N/A"))))))) -> t | AL3: =IF($G$38="Mandag","o",IF($G$38="Tirsdag","t",IF($G$38="Onsdag","f",IF($G$38="Torsdag","l",IF($G$38="Fredag","s",IF($G$38="Lørdag","m",IF($G$38="Søndag","t","N/A"))))))) -> o | AM3: =IF($G$38="Mandag","t",IF($G$38="Tirsdag","f",IF($G$38="Onsdag","l",IF($G$38="Torsdag","s",IF($G$38="Fredag","m",IF($G$38="Lørdag","t",IF($G$38="Søndag","o","N/A"))))))) -> t | AN3: =IF($G$38="Mandag","f",IF($G$38="Tirsdag","l",IF($G$38="Onsdag","s",IF($G$38="Torsdag","m",IF($G$38="Fredag","t",IF($G$38="Lørdag","o",IF($G$38="Søndag","t","N/A"))))))) -> f | AO3: =IF($G$38="Mandag","l",IF($G$38="Tirsdag","s",IF($G$38="Onsdag","m",IF($G$38="Torsdag","t",IF($G$38="Fredag","o",IF($G$38="Lørdag","t",IF($G$38="Søndag","f","N/A"))))))) -> l | AP3: =IF($G$38="Mandag","s",IF($G$38="Tirsdag","m",IF($G$38="Onsdag","t",IF($G$38="Torsdag","o",IF($G$38="Fredag","t",IF($G$38="Lørdag","f",IF($G$38="Søndag","l","N/A"))))))) -> s | AQ3: =IF($G$38="Mandag","m",IF($G$38="Tirsdag","t",IF($G$38="Onsdag","o",IF($G$38="Torsdag","t",IF($G$38="Fredag","f",IF($G$38="Lørdag","l",IF($G$38="Søndag","s","N/A"))))))) -> m | AR3: =IF($G$38="Mandag","t",IF($G$38="Tirsdag","o",IF($G$38="Onsdag","t",IF($G$38="Torsdag","f",IF($G$38="Fredag","l",IF($G$38="Lørdag","s",IF($G$38="Søndag","m","N/A"))))))) -> t | AS3: =IF($G$38="Mandag","o",IF($G$38="Tirsdag","t",IF($G$38="Onsdag","f",IF($G$38="Torsdag","l",IF($G$38="Fredag","s",IF($G$38="Lørdag","m",IF($G$38="Søndag","t","N/A"))))))) -> o | AT3: =IF($G$38="Mandag","t",IF($G$38="Tirsdag","f",IF($G$38="Onsdag","l",IF($G$38="Torsdag","s",IF($G$38="Fredag","m",IF($G$38="Lørdag","t",IF($G$38="Søndag","o","N/A"))))))) -> t | AU3: =IF($G$38="Mandag","f",IF($G$38="Tirsdag","l",IF($G$38="Onsdag","s",IF($G$38="Torsdag","m",IF($G$38="Fredag","t",IF($G$38="Lørdag","o",IF($G$38="Søndag","t","N/A"))))))) -> f | AV3: =IF($G$38="Mandag","l",IF($G$38="Tirsdag","s",IF($G$38="Onsdag","m",IF($G$38="Torsdag","t",IF($G$38="Fredag","o",IF($G$38="Lørdag","t",IF($G$38="Søndag","f","N/A"))))))) -> l | AW3: =IF($G$38="Mandag","s",IF($G$38="Tirsdag","m",IF($G$38="Onsdag","t",IF($G$38="Torsdag","o",IF($G$38="Fredag","t",IF($G$38="Lørdag","f",IF($G$38="Søndag","l","N/A"))))))) -> s | AX3: =IF($G$38="Mandag","m",IF($G$38="Tirsdag","t",IF($G$38="Onsdag","o",IF($G$38="Torsdag","t",IF($G$38="Fredag","f",IF($G$38="Lørdag","l",IF($G$38="Søndag","s","N/A"))))))) -> m | AY3: =IF($G$38="Mandag","t",IF($G$38="Tirsdag","o",IF($G$38="Onsdag","t",IF($G$38="Torsdag","f",IF($G$38="Fredag","l",IF($G$38="Lørdag","s",IF($G$38="Søndag","m","N/A"))))))) -> t | AZ3: =IF($G$38="Mandag","o",IF($G$38="Tirsdag","t",IF($G$38="Onsdag","f",IF($G$38="Torsdag","l",IF($G$38="Fredag","s",IF($G$38="Lørdag","m",IF($G$38="Søndag","t","N/A"))))))) -> o | BA3: =IF($G$38="Mandag","t",IF($G$38="Tirsdag","f",IF($G$38="Onsdag","l",IF($G$38="Torsdag","s",IF($G$38="Fredag","m",IF($G$38="Lørdag","t",IF($G$38="Søndag","o","N/A"))))))) -> t | BB3: =IF($G$38="Mandag","f",IF($G$38="Tirsdag","l",IF($G$38="Onsdag","s",IF($G$38="Torsdag","m",IF($G$38="Fredag","t",IF($G$38="Lørdag","o",IF($G$38="Søndag","t","N/A"))))))) -> f | BC3: =IF($G$38="Mandag","l",IF($G$38="Tirsdag","s",IF($G$38="Onsdag","m",IF($G$38="Torsdag","t",IF($G$38="Fredag","o",IF($G$38="Lørdag","t",IF($G$38="Søndag","f","N/A"))))))) -> l | BD3: =IF($G$38="Mandag","s",IF($G$38="Tirsdag","m",IF($G$38="Onsdag","t",IF($G$38="Torsdag","o",IF($G$38="Fredag","t",IF($G$38="Lørdag","f",IF($G$38="Søndag","l","N/A"))))))) -> s | BE3: =IF($G$38="Mandag","m",IF($G$38="Tirsdag","t",IF($G$38="Onsdag","o",IF($G$38="Torsdag","t",IF($G$38="Fredag","f",IF($G$38="Lørdag","l",IF($G$38="Søndag","s","N/A"))))))) -> m | BF3: =IF($G$38="Mandag","t",IF($G$38="Tirsdag","o",IF($G$38="Onsdag","t",IF($G$38="Torsdag","f",IF($G$38="Fredag","l",IF($G$38="Lørdag","s",IF($G$38="Søndag","m","N/A"))))))) -> t | BG3: =IF($G$38="Mandag","o",IF($G$38="Tirsdag","t",IF($G$38="Onsdag","f",IF($G$38="Torsdag","l",IF($G$38="Fredag","s",IF($G$38="Lørdag","m",IF($G$38="Søndag","t","N/A"))))))) -> o | BH3: =IF($G$38="Mandag","t",IF($G$38="Tirsdag","f",IF($G$38="Onsdag","l",IF($G$38="Torsdag","s",IF($G$38="Fredag","m",IF($G$38="Lørdag","t",IF($G$38="Søndag","o","N/A"))))))) -> t | BI3: =IF($G$38="Mandag","f",IF($G$38="Tirsdag","l",IF($G$38="Onsdag","s",IF($G$38="Torsdag","m",IF($G$38="Fredag","t",IF($G$38="Lørdag","o",IF($G$38="Søndag","t","N/A"))))))) -> f | BJ3: =IF($G$38="Mandag","l",IF($G$38="Tirsdag","s",IF($G$38="Onsdag","m",IF($G$38="Torsdag","t",IF($G$38="Fredag","o",IF($G$38="Lørdag","t",IF($G$38="Søndag","f","N/A"))))))) -> l | BK3: =IF($G$38="Mandag","s",IF($G$38="Tirsdag","m",IF($G$38="Onsdag","t",IF($G$38="Torsdag","o",IF($G$38="Fredag","t",IF($G$38="Lørdag","f",IF($G$38="Søndag","l","N/A"))))))) -> s | BL3: =IF($G$38="Mandag","m",IF($G$38="Tirsdag","t",IF($G$38="Onsdag","o",IF($G$38="Torsdag","t",IF($G$38="Fredag","f",IF($G$38="Lørdag","l",IF($G$38="Søndag","s","N/A"))))))) -> m | BM3: =IF($G$38="Mandag","t",IF($G$38="Tirsdag","o",IF($G$38="Onsdag","t",IF($G$38="Torsdag","f",IF($G$38="Fredag","l",IF($G$38="Lørdag","s",IF($G$38="Søndag","m","N/A"))))))) -> t | BN3: =IF($G$38="Mandag","o",IF($G$38="Tirsdag","t",IF($G$38="Onsdag","f",IF($G$38="Torsdag","l",IF($G$38="Fredag","s",IF($G$38="Lørdag","m",IF($G$38="Søndag","t","N/A"))))))) -> o | BO3: =IF($G$38="Mandag","t",IF($G$38="Tirsdag","f",IF($G$38="Onsdag","l",IF($G$38="Torsdag","s",IF($G$38="Fredag","m",IF($G$38="Lørdag","t",IF($G$38="Søndag","o","N/A"))))))) -> t | BP3: =IF($G$38="Mandag","f",IF($G$38="Tirsdag","l",IF($G$38="Onsdag","s",IF($G$38="Torsdag","m",IF($G$38="Fredag","t",IF($G$38="Lørdag","o",IF($G$38="Søndag","t","N/A"))))))) -> f | BQ3: =IF($G$38="Mandag","l",IF($G$38="Tirsdag","s",IF($G$38="Onsdag","m",IF($G$38="Torsdag","t",IF($G$38="Fredag","o",IF($G$38="Lørdag","t",IF($G$38="Søndag","f","N/A"))))))) -> l | BR3: =IF($G$38="Mandag","s",IF($G$38="Tirsdag","m",IF($G$38="Onsdag","t",IF($G$38="Torsdag","o",IF($G$38="Fredag","t",IF($G$38="Lørdag","f",IF($G$38="Søndag","l","N/A"))))))) -> s | BS3: =IF($G$38="Mandag","m",IF($G$38="Tirsdag","t",IF($G$38="Onsdag","o",IF($G$38="Torsdag","t",IF($G$38="Fredag","f",IF($G$38="Lørdag","l",IF($G$38="Søndag","s","N/A"))))))) -> m | BT3: =IF($G$38="Mandag","t",IF($G$38="Tirsdag","o",IF($G$38="Onsdag","t",IF($G$38="Torsdag","f",IF($G$38="Fredag","l",IF($G$38="Lørdag","s",IF($G$38="Søndag","m","N/A"))))))) -> t | BU3: =IF($G$38="Mandag","o",IF($G$38="Tirsdag","t",IF($G$38="Onsdag","f",IF($G$38="Torsdag","l",IF($G$38="Fredag","s",IF($G$38="Lørdag","m",IF($G$38="Søndag","t","N/A"))))))) -> o | BV3: =IF($G$38="Mandag","t",IF($G$38="Tirsdag","f",IF($G$38="Onsdag","l",IF($G$38="Torsdag","s",IF($G$38="Fredag","m",IF($G$38="Lørdag","t",IF($G$38="Søndag","o","N/A"))))))) -> t | BW3: =IF($G$38="Mandag","f",IF($G$38="Tirsdag","l",IF($G$38="Onsdag","s",IF($G$38="Torsdag","m",IF($G$38="Fredag","t",IF($G$38="Lørdag","o",IF($G$38="Søndag","t","N/A"))))))) -> f | BX3: =IF($G$38="Mandag","l",IF($G$38="Tirsdag","s",IF($G$38="Onsdag","m",IF($G$38="Torsdag","t",IF($G$38="Fredag","o",IF($G$38="Lørdag","t",IF($G$38="Søndag","f","N/A"))))))) -> l | BY3: =IF($G$38="Mandag","s",IF($G$38="Tirsdag","m",IF($G$38="Onsdag","t",IF($G$38="Torsdag","o",IF($G$38="Fredag","t",IF($G$38="Lørdag","f",IF($G$38="Søndag","l","N/A"))))))) -> s | BZ3: =IF($G$38="Mandag","m",IF($G$38="Tirsdag","t",IF($G$38="Onsdag","o",IF($G$38="Torsdag","t",IF($G$38="Fredag","f",IF($G$38="Lørdag","l",IF($G$38="Søndag","s","N/A"))))))) -> m | CA3: =IF($G$38="Mandag","t",IF($G$38="Tirsdag","o",IF($G$38="Onsdag","t",IF($G$38="Torsdag","f",IF($G$38="Fredag","l",IF($G$38="Lørdag","s",IF($G$38="Søndag","m","N/A"))))))) -> t | CB3: =IF($G$38="Mandag","o",IF($G$38="Tirsdag","t",IF($G$38="Onsdag","f",IF($G$38="Torsdag","l",IF($G$38="Fredag","s",IF($G$38="Lørdag","m",IF($G$38="Søndag","t","N/A"))))))) -> o | CC3: =IF($G$38="Mandag","t",IF($G$38="Tirsdag","f",IF($G$38="Onsdag","l",IF($G$38="Torsdag","s",IF($G$38="Fredag","m",IF($G$38="Lørdag","t",IF($G$38="Søndag","o","N/A"))))))) -> t | CD3: =IF($G$38="Mandag","f",IF($G$38="Tirsdag","l",IF($G$38="Onsdag","s",IF($G$38="Torsdag","m",IF($G$38="Fredag","t",IF($G$38="Lørdag","o",IF($G$38="Søndag","t","N/A"))))))) -> f | CE3: =IF($G$38="Mandag","l",IF($G$38="Tirsdag","s",IF($G$38="Onsdag","m",IF($G$38="Torsdag","t",IF($G$38="Fredag","o",IF($G$38="Lørdag","t",IF($G$38="Søndag","f","N/A"))))))) -> l | CF3: =IF($G$38="Mandag","s",IF($G$38="Tirsdag","m",IF($G$38="Onsdag","t",IF($G$38="Torsdag","o",IF($G$38="Fredag","t",IF($G$38="Lørdag","f",IF($G$38="Søndag","l","N/A"))))))) -> s | CG3: Vakt lokasjon | CH3: Fra kl | CI3: Til kl | CJ3: Timer | CK3: Pause | CL3: SUM
A4: A | B4: A | C4: A | D4: A | E4: A | F4: A | CG4: Vakt 1 | CH4: 0.29166667 | CI4: 0.83333333 | CJ4: =IF(AND(CH4=0,CI4=0),0,IF(CH4<CI4,((CI4-CH4)*24)-CK4,(((1-CH4)+CI4)*24)-CK4)) -> 12.5 | CK4: 0.5 | CL4: =COUNTIF(A4:CF4,"> ")*CJ4 -> 75 | CM4: 1
A5: B | B5: B | C5: B | D5: B | E5: B | F5: B | CG5: Vakt 2 | CH5: 0.29166667 | CI5: 0.625 | CJ5: =IF(AND(CH5=0,CI5=0),0,IF(CH5<CI5,((CI5-CH5)*24)-CK5,(((1-CH5)+CI5)*24)-CK5)) -> 8 | CL5: =COUNTIF(A5:CF5,"> ")*CJ5 -> 48 | CM5: 2
CJ6: =IF(AND(CH6=0,CI6=0),0,IF(CH6<CI6,((CI6-CH6)*24)-CK6,(((1-CH6)+CI6)*24)-CK6)) -> 0 | CL6: =COUNTIF(A6:CF6,"> ")*CJ6 -> 0 | CM6: 1
CJ7: =IF(AND(CH7=0,CI7=0),0,IF(CH7<CI7,((CI7-CH7)*24)-CK7,(((1-CH7)+CI7)*24)-CK7)) -> 0 | CL7: =COUNTIF(A7:CF7,"> ")*CJ7 -> 0 | CM7: 2
CJ8: =IF(AND(CH8=0,CI8=0),0,IF(CH8<CI8,((CI8-CH8)*24)-CK8,(((1-CH8)+CI8)*24)-CK8)) -> 0 | CL8: =COUNTIF(A8:CF8,"> ")*CJ8 -> 0 | CM8: 1
CJ9: =IF(AND(CH9=0,CI9=0),0,IF(CH9<CI9,((CI9-CH9)*24)-CK9,(((1-CH9)+CI9)*24)-CK9)) -> 0 | CL9: =COUNTIF(A9:CF9,"> ")*CJ9 -> 0 | CM9: 2 | CQ9: Ukedag dropdown
CJ10: =IF(AND(CH10=0,CI10=0),0,IF(CH10<CI10,((CI10-CH10)*24)-CK10,(((1-CH10)+CI10)*24)-CK10)) -> 0 | CL10: =COUNTIF(A10:CF10,"> ")*CJ10 -> 0 | CM10: 1 | CQ10: Mandag
CJ11: =IF(AND(CH11=0,CI11=0),0,IF(CH11<CI11,((CI11-CH11)*24)-CK11,(((1-CH11)+CI11)*24)-CK11)) -> 0 | CL11: =COUNTIF(A11:CF11,"> ")*CJ11 -> 0 | CM11: 2 | CQ11: Tirsdag
CJ12: =IF(AND(CH12=0,CI12=0),0,IF(CH12<CI12,((CI12-CH12)*24)-CK12,(((1-CH12)+CI12)*24)-CK12)) -> 0 | CL12: =COUNTIF(A12:CF12,"> ")*CJ12 -> 0 | CM12: 1 | CQ12: Onsdag
CJ13: =IF(AND(CH13=0,CI13=0),0,IF(CH13<CI13,((CI13-CH13)*24)-CK13,(((1-CH13)+CI13)*24)-CK13)) -> 0 | CL13: =COUNTIF(A13:CF13,"> ")*CJ13 -> 0 | CM13: 2 | CQ13: Torsdag
CJ14: =IF(AND(CH14=0,CI14=0),0,IF(CH14<CI14,((CI14-CH14)*24)-CK14,(((1-CH14)+CI14)*24)-CK14)) -> 0 | CL14: =COUNTIF(A14:CF14,"> ")*CJ14 -> 0 | CM14: 1 | CQ14: Fredag
CJ15: =IF(AND(CH15=0,CI15=0),0,IF(CH15<CI15,((CI15-CH15)*24)-CK15,(((1-CH15)+CI15)*24)-CK15)) -> 0 | CL15: =COUNTIF(A15:CF15,"> ")*CJ15 -> 0 | CM15: 2 | CQ15: Lørdag
CJ16: =IF(AND(CH16=0,CI16=0),0,IF(CH16<CI16,((CI16-CH16)*24)-CK16,(((1-CH16)+CI16)*24)-CK16)) -> 0 | CL16: =COUNTIF(A16:CF16,"> ")*CJ16 -> 0 | CM16: 1 | CQ16: Søndag
CJ17: =IF(AND(CH17=0,CI17=0),0,IF(CH17<CI17,((CI17-CH17)*24)-CK17,(((1-CH17)+CI17)*24)-CK17)) -> 0 | CL17: =COUNTIF(A17:CF17,"> ")*CJ17 -> 0 | CM17: 2
CJ18: =IF(AND(CH18=0,CI18=0),0,IF(CH18<CI18,((CI18-CH18)*24)-CK18,(((1-CH18)+CI18)*24)-CK18)) -> 0 | CL18: =COUNTIF(A18:CF18,"> ")*CJ18 -> 0 | CM18: 1
CJ19: =IF(AND(CH19=0,CI19=0),0,IF(CH19<CI19,((CI19-CH19)*24)-CK19,(((1-CH19)+CI19)*24)-CK19)) -> 0 | CL19: =COUNTIF(A19:CF19,"> ")*CJ19 -> 0 | CM19: 2
CJ20: =IF(AND(CH20=0,CI20=0),0,IF(CH20<CI20,((CI20-CH20)*24)-CK20,(((1-CH20)+CI20)*24)-CK20)) -> 0 | CL20: =COUNTIF(A20:CF20,"> ")*CJ20 -> 0 | CM20: 1
CJ21: =IF(AND(CH21=0,CI21=0),0,IF(CH21<CI21,((CI21-CH21)*24)-CK21,(((1-CH21)+CI21)*24)-CK21)) -> 0 | CL21: =COUNTIF(A21:CF21,"> ")*CJ21 -> 0 | CM21: 2
CJ22: =IF(AND(CH22=0,CI22=0),0,IF(CH22<CI22,((CI22-CH22)*24)-CK22,(((1-CH22)+CI22)*24)-CK22)) -> 0 | CL22: =COUNTIF(A22:CF22,"> ")*CJ22 -> 0 | CM22: 1
CJ23: =IF(AND(CH23=0,CI23=0),0,IF(CH23<CI23,((CI23-CH23)*24)-CK23,(((1-CH23)+CI23)*24)-CK23)) -> 0 | CL23: =COUNTIF(A23:CF23,"> ")*CJ23 -> 0 | CM23: 2
CJ24: =IF(AND(CH24=0,CI24=0),0,IF(CH24<CI24,((CI24-CH24)*24)-CK24,(((1-CH24)+CI24)*24)-CK24)) -> 0 | CL24: =COUNTIF(A24:CF24,"> ")*CJ24 -> 0 | CM24: 1
CJ25: =IF(AND(CH25=0,CI25=0),0,IF(CH25<CI25,((CI25-CH25)*24)-CK25,(((1-CH25)+CI25)*24)-CK25)) -> 0 | CL25: =COUNTIF(A25:CF25,"> ")*CJ25 -> 0 | CM25: 2 | CQ25: =DATE(2016,1,26) -> 42395
CJ26: =IF(AND(CH26=0,CI26=0),0,IF(CH26<CI26,((CI26-CH26)*24)-CK26,(((1-CH26)+CI26)*24)-CK26)) -> 0 | CL26: =COUNTIF(A26:CF26,"> ")*CJ26 -> 0 | CM26: 1
CJ27: =IF(AND(CH27=0,CI27=0),0,IF(CH27<CI27,((CI27-CH27)*24)-CK27,(((1-CH27)+CI27)*24)-CK27)) -> 0 | CL27: =COUNTIF(A27:CF27,"> ")*CJ27 -> 0 | CM27: 2 | CQ27: =TEXT(CQ25,"dddd") -> Tuesday
CJ28: =IF(AND(CH28=0,CI28=0),0,IF(CH28<CI28,((CI28-CH28)*24)-CK28,(((1-CH28)+CI28)*24)-CK28)) -> 0 | CL28: =COUNTIF(A28:CF28,"> ")*CJ28 -> 0 | CM28: 1
CJ29: =IF(AND(CH29=0,CI29=0),0,IF(CH29<CI29,((CI29-CH29)*24)-CK29,(((1-CH29)+CI29)*24)-CK29)) -> 0 | CL29: =COUNTIF(A29:CF29,"> ")*CJ29 -> 0 | CM29: 2
CJ30: =IF(AND(CH30=0,CI30=0),0,IF(CH30<CI30,((CI30-CH30)*24)-CK30,(((1-CH30)+CI30)*24)-CK30)) -> 0 | CL30: =COUNTIF(A30:CF30,"> ")*CJ30 -> 0 | CM30: 1
CJ31: =IF(AND(CH31=0,CI31=0),0,IF(CH31<CI31,((CI31-CH31)*24)-CK31,(((1-CH31)+CI31)*24)-CK31)) -> 0 | CL31: =COUNTIF(A31:CF31,"> ")*CJ31 -> 0 | CM31: 2
CJ32: =IF(AND(CH32=0,CI32=0),0,IF(CH32<CI32,((CI32-CH32)*24)-CK32,(((1-CH32)+CI32)*24)-CK32)) -> 0 | CL32: =COUNTIF(A32:CF32,"> ")*CJ32 -> 0 | CM32: 1
CJ33: =IF(AND(CH33=0,CI33=0),0,IF(CH33<CI33,((CI33-CH33)*24)-CK33,(((1-CH33)+CI33)*24)-CK33)) -> 0 | CL33: =COUNTIF(A33:CF33,"> ")*CJ33 -> 0 | CM33: 2
CJ34: =IF(AND(CH34=0,CI34=0),0,IF(CH34<CI34,((CI34-CH34)*24)-CK34,(((1-CH34)+CI34)*24)-CK34)) -> 0 | CL34: =COUNTIF(A34:CF34,"> ")*CJ34 -> 0 | CM34: 1
CJ35: =IF(AND(CH35=0,CI35=0),0,IF(CH35<CI35,((CI35-CH35)*24)-CK35,(((1-CH35)+CI35)*24)-CK35)) -> 0 | CL35: =COUNTIF(A35:CF35,"> ")*CJ35 -> 0 | CM35: 2
A36: =IF($G$38="Mandag","m",IF($G$38="Tirsdag","t",IF($G$38="Onsdag","o",IF($G$38="Torsdag","t",IF($G$38="Fredag","f",IF($G$38="Lørdag","l",IF($G$38="Søndag","s","N/A"))))))) -> m | B36: =IF($G$38="Mandag","t",IF($G$38="Tirsdag","o",IF($G$38="Onsdag","t",IF($G$38="Torsdag","f",IF($G$38="Fredag","l",IF($G$38="Lørdag","s",IF($G$38="Søndag","m","N/A"))))))) -> t | C36: =IF($G$38="Mandag","o",IF($G$38="Tirsdag","t",IF($G$38="Onsdag","f",IF($G$38="Torsdag","l",IF($G$38="Fredag","s",IF($G$38="Lørdag","m",IF($G$38="Søndag","t","N/A"))))))) -> o | D36: =IF($G$38="Mandag","t",IF($G$38="Tirsdag","f",IF($G$38="Onsdag","l",IF($G$38="Torsdag","s",IF($G$38="Fredag","m",IF($G$38="Lørdag","t",IF($G$38="Søndag","o","N/A"))))))) -> t | E36: =IF($G$38="Mandag","f",IF($G$38="Tirsdag","l",IF($G$38="Onsdag","s",IF($G$38="Torsdag","m",IF($G$38="Fredag","t",IF($G$38="Lørdag","o",IF($G$38="Søndag","t","N/A"))))))) -> f | F36: =IF($G$38="Mandag","l",IF($G$38="Tirsdag","s",IF($G$38="Onsdag","m",IF($G$38="Torsdag","t",IF($G$38="Fredag","o",IF($G$38="Lørdag","t",IF($G$38="Søndag","f","N/A"))))))) -> l | G36: =IF($G$38="Mandag","s",IF($G$38="Tirsdag","m",IF($G$38="Onsdag","t",IF($G$38="Torsdag","o",IF($G$38="Fredag","t",IF($G$38="Lørdag","f",IF($G$38="Søndag","l","N/A"))))))) -> s | H36: =IF($G$38="Mandag","m",IF($G$38="Tirsdag","t",IF($G$38="Onsdag","o",IF($G$38="Torsdag","t",IF($G$38="Fredag","f",IF($G$38="Lørdag","l",IF($G$38="Søndag","s","N/A"))))))) -> m | I36: =IF($G$38="Mandag","t",IF($G$38="Tirsdag","o",IF($G$38="Onsdag","t",IF($G$38="Torsdag","f",IF($G$38="Fredag","l",IF($G$38="Lørdag","s",IF($G$38="Søndag","m","N/A"))))))) -> t | J36: =IF($G$38="Mandag","o",IF($G$38="Tirsdag","t",IF($G$38="Onsdag","f",IF($G$38="Torsdag","l",IF($G$38="Fredag","s",IF($G$38="Lørdag","m",IF($G$38="Søndag","t","N/A"))))))) -> o | K36: =IF($G$38="Mandag","t",IF($G$38="Tirsdag","f",IF($G$38="Onsdag","l",IF($G$38="Torsdag","s",IF($G$38="Fredag","m",IF($G$38="Lørdag","t",IF($G$38="Søndag","o","N/A"))))))) -> t | L36: =IF($G$38="Mandag","f",IF($G$38="Tirsdag","l",IF($G$38="Onsdag","s",IF($G$38="Torsdag","m",IF($G$38="Fredag","t",IF($G$38="Lørdag","o",IF($G$38="Søndag","t","N/A"))))))) -> f | M36: =IF($G$38="Mandag","l",IF($G$38="Tirsdag","s",IF($G$38="Onsdag","m",IF($G$38="Torsdag","t",IF($G$38="Fredag","o",IF($G$38="Lørdag","t",IF($G$38="Søndag","f","N/A"))))))) -> l | N36: =IF($G$38="Mandag","s",IF($G$38="Tirsdag","m",IF($G$38="Onsdag","t",IF($G$38="Torsdag","o",IF($G$38="Fredag","t",IF($G$38="Lørdag","f",IF($G$38="Søndag","l","N/A"))))))) -> s | O36: =IF($G$38="Mandag","m",IF($G$38="Tirsdag","t",IF($G$38="Onsdag","o",IF($G$38="Torsdag","t",IF($G$38="Fredag","f",IF($G$38="Lørdag","l",IF($G$38="Søndag","s","N/A"))))))) -> m | P36: =IF($G$38="Mandag","t",IF($G$38="Tirsdag","o",IF($G$38="Onsdag","t",IF($G$38="Torsdag","f",IF($G$38="Fredag","l",IF($G$38="Lørdag","s",IF($G$38="Søndag","m","N/A"))))))) -> t | Q36: =IF($G$38="Mandag","o",IF($G$38="Tirsdag","t",IF($G$38="Onsdag","f",IF($G$38="Torsdag","l",IF($G$38="Fredag","s",IF($G$38="Lørdag","m",IF($G$38="Søndag","t","N/A"))))))) -> o | R36: =IF($G$38="Mandag","t",IF($G$38="Tirsdag","f",IF($G$38="Onsdag","l",IF($G$38="Torsdag","s",IF($G$38="Fredag","m",IF($G$38="Lørdag","t",IF($G$38="Søndag","o","N/A"))))))) -> t | S36: =IF($G$38="Mandag","f",IF($G$38="Tirsdag","l",IF($G$38="Onsdag","s",IF($G$38="Torsdag","m",IF($G$38="Fredag","t",IF($G$38="Lørdag","o",IF($G$38="Søndag","t","N/A"))))))) -> f | T36: =IF($G$38="Mandag","l",IF($G$38="Tirsdag","s",IF($G$38="Onsdag","m",IF($G$38="Torsdag","t",IF($G$38="Fredag","o",IF($G$38="Lørdag","t",IF($G$38="Søndag","f","N/A"))))))) -> l | U36: =IF($G$38="Mandag","s",IF($G$38="Tirsdag","m",IF($G$38="Onsdag","t",IF($G$38="Torsdag","o",IF($G$38="Fredag","t",IF($G$38="Lørdag","f",IF($G$38="Søndag","l","N/A"))))))) -> s | V36: =IF($G$38="Mandag","m",IF($G$38="Tirsdag","t",IF($G$38="Onsdag","o",IF($G$38="Torsdag","t",IF($G$38="Fredag","f",IF($G$38="Lørdag","l",IF($G$38="Søndag","s","N/A"))))))) -> m | W36: =IF($G$38="Mandag","t",IF($G$38="Tirsdag","o",IF($G$38="Onsdag","t",IF($G$38="Torsdag","f",IF($G$38="Fredag","l",IF($G$38="Lørdag","s",IF($G$38="Søndag","m","N/A"))))))) -> t | X36: =IF($G$38="Mandag","o",IF($G$38="Tirsdag","t",IF($G$38="Onsdag","f",IF($G$38="Torsdag","l",IF($G$38="Fredag","s",IF($G$38="Lørdag","m",IF($G$38="Søndag","t","N/A"))))))) -> o | Y36: =IF($G$38="Mandag","t",IF($G$38="Tirsdag","f",IF($G$38="Onsdag","l",IF($G$38="Torsdag","s",IF($G$38="Fredag","m",IF($G$38="Lørdag","t",IF($G$38="Søndag","o","N/A"))))))) -> t | Z36: =IF($G$38="Mandag","f",IF($G$38="Tirsdag","l",IF($G$38="Onsdag","s",IF($G$38="Torsdag","m",IF($G$38="Fredag","t",IF($G$38="Lørdag","o",IF($G$38="Søndag","t","N/A"))))))) -> f | AA36: =IF($G$38="Mandag","l",IF($G$38="Tirsdag","s",IF($G$38="Onsdag","m",IF($G$38="Torsdag","t",IF($G$38="Fredag","o",IF($G$38="Lørdag","t",IF($G$38="Søndag","f","N/A"))))))) -> l | AB36: =IF($G$38="Mandag","s",IF($G$38="Tirsdag","m",IF($G$38="Onsdag","t",IF($G$38="Torsdag","o",IF($G$38="Fredag","t",IF($G$38="Lørdag","f",IF($G$38="Søndag","l","N/A"))))))) -> s | AC36: =IF($G$38="Mandag","m",IF($G$38="Tirsdag","t",IF($G$38="Onsdag","o",IF($G$38="Torsdag","t",IF($G$38="Fredag","f",IF($G$38="Lørdag","l",IF($G$38="Søndag","s","N/A"))))))) -> m | AD36: =IF($G$38="Mandag","t",IF($G$38="Tirsdag","o",IF($G$38="Onsdag","t",IF($G$38="Torsdag","f",IF($G$38="Fredag","l",IF($G$38="Lørdag","s",IF($G$38="Søndag","m","N/A"))))))) -> t | AE36: =IF($G$38="Mandag","o",IF($G$38="Tirsdag","t",IF($G$38="Onsdag","f",IF($G$38="Torsdag","l",IF($G$38="Fredag","s",IF($G$38="Lørdag","m",IF($G$38="Søndag","t","N/A"))))))) -> o | AF36: =IF($G$38="Mandag","t",IF($G$38="Tirsdag","f",IF($G$38="Onsdag","l",IF($G$38="Torsdag","s",IF($G$38="Fredag","m",IF($G$38="Lørdag","t",IF($G$38="Søndag","o","N/A"))))))) -> t | AG36: =IF($G$38="Mandag","f",IF($G$38="Tirsdag","l",IF($G$38="Onsdag","s",IF($G$38="Torsdag","m",IF($G$38="Fredag","t",IF($G$38="Lørdag","o",IF($G$38="Søndag","t","N/A"))))))) -> f | AH36: =IF($G$38="Mandag","l",IF($G$38="Tirsdag","s",IF($G$38="Onsdag","m",IF($G$38="Torsdag","t",IF($G$38="Fredag","o",IF($G$38="Lørdag","t",IF($G$38="Søndag","f","N/A"))))))) -> l | AI36: =IF($G$38="Mandag","s",IF($G$38="Tirsdag","m",IF($G$38="Onsdag","t",IF($G$38="Torsdag","o",IF($G$38="Fredag","t",IF($G$38="Lørdag","f",IF($G$38="Søndag","l","N/A"))))))) -> s | AJ36: =IF($G$38="Mandag","m",IF($G$38="Tirsdag","t",IF($G$38="Onsdag","o",IF($G$38="Torsdag","t",IF($G$38="Fredag","f",IF($G$38="Lørdag","l",IF($G$38="Søndag","s","N/A"))))))) -> m | AK36: =IF($G$38="Mandag","t",IF($G$38="Tirsdag","o",IF($G$38="Onsdag","t",IF($G$38="Torsdag","f",IF($G$38="Fredag","l",IF($G$38="Lørdag","s",IF($G$38="Søndag","m","N/A"))))))) -> t | AL36: =IF($G$38="Mandag","o",IF($G$38="Tirsdag","t",IF($G$38="Onsdag","f",IF($G$38="Torsdag","l",IF($G$38="Fredag","s",IF($G$38="Lørdag","m",IF($G$38="Søndag","t","N/A"))))))) -> o | AM36: =IF($G$38="Mandag","t",IF($G$38="Tirsdag","f",IF($G$38="Onsdag","l",IF($G$38="Torsdag","s",IF($G$38="Fredag","m",IF($G$38="Lørdag","t",IF($G$38="Søndag","o","N/A"))))))) -> t | AN36: =IF($G$38="Mandag","f",IF($G$38="Tirsdag","l",IF($G$38="Onsdag","s",IF($G$38="Torsdag","m",IF($G$38="Fredag","t",IF($G$38="Lørdag","o",IF($G$38="Søndag","t","N/A"))))))) -> f | AO36: =IF($G$38="Mandag","l",IF($G$38="Tirsdag","s",IF($G$38="Onsdag","m",IF($G$38="Torsdag","t",IF($G$38="Fredag","o",IF($G$38="Lørdag","t",IF($G$38="Søndag","f","N/A"))))))) -> l | AP36: =IF($G$38="Mandag","s",IF($G$38="Tirsdag","m",IF($G$38="Onsdag","t",IF($G$38="Torsdag","o",IF($G$38="Fredag","t",IF($G$38="Lørdag","f",IF($G$38="Søndag","l","N/A"))))))) -> s | AQ36: =IF($G$38="Mandag","m",IF($G$38="Tirsdag","t",IF($G$38="Onsdag","o",IF($G$38="Torsdag","t",IF($G$38="Fredag","f",IF($G$38="Lørdag","l",IF($G$38="Søndag","s","N/A"))))))) -> m | AR36: =IF($G$38="Mandag","t",IF($G$38="Tirsdag","o",IF($G$38="Onsdag","t",IF($G$38="Torsdag","f",IF($G$38="Fredag","l",IF($G$38="Lørdag","s",IF($G$38="Søndag","m","N/A"))))))) -> t | AS36: =IF($G$38="Mandag","o",IF($G$38="Tirsdag","t",IF($G$38="Onsdag","f",IF($G$38="Torsdag","l",IF($G$38="Fredag","s",IF($G$38="Lørdag","m",IF($G$38="Søndag","t","N/A"))))))) -> o | AT36: =IF($G$38="Mandag","t",IF($G$38="Tirsdag","f",IF($G$38="Onsdag","l",IF($G$38="Torsdag","s",IF($G$38="Fredag","m",IF($G$38="Lørdag","t",IF($G$38="Søndag","o","N/A"))))))) -> t | AU36: =IF($G$38="Mandag","f",IF($G$38="Tirsdag","l",IF($G$38="Onsdag","s",IF($G$38="Torsdag","m",IF($G$38="Fredag","t",IF($G$38="Lørdag","o",IF($G$38="Søndag","t","N/A"))))))) -> f | AV36: =IF($G$38="Mandag","l",IF($G$38="Tirsdag","s",IF($G$38="Onsdag","m",IF($G$38="Torsdag","t",IF($G$38="Fredag","o",IF($G$38="Lørdag","t",IF($G$38="Søndag","f","N/A"))))))) -> l | AW36: =IF($G$38="Mandag","s",IF($G$38="Tirsdag","m",IF($G$38="Onsdag","t",IF($G$38="Torsdag","o",IF($G$38="Fredag","t",IF($G$38="Lørdag","f",IF($G$38="Søndag","l","N/A"))))))) -> s | AX36: =IF($G$38="Mandag","m",IF($G$38="Tirsdag","t",IF($G$38="Onsdag","o",IF($G$38="Torsdag","t",IF($G$38="Fredag","f",IF($G$38="Lørdag","l",IF($G$38="Søndag","s","N/A"))))))) -> m | AY36: =IF($G$38="Mandag","t",IF($G$38="Tirsdag","o",IF($G$38="Onsdag","t",IF($G$38="Torsdag","f",IF($G$38="Fredag","l",IF($G$38="Lørdag","s",IF($G$38="Søndag","m","N/A"))))))) -> t | AZ36: =IF($G$38="Mandag","o",IF($G$38="Tirsdag","t",IF($G$38="Onsdag","f",IF($G$38="Torsdag","l",IF($G$38="Fredag","s",IF($G$38="Lørdag","m",IF($G$38="Søndag","t","N/A"))))))) -> o | BA36: =IF($G$38="Mandag","t",IF($G$38="Tirsdag","f",IF($G$38="Onsdag","l",IF($G$38="Torsdag","s",IF($G$38="Fredag","m",IF($G$38="Lørdag","t",IF($G$38="Søndag","o","N/A"))))))) -> t | BB36: =IF($G$38="Mandag","f",IF($G$38="Tirsdag","l",IF($G$38="Onsdag","s",IF($G$38="Torsdag","m",IF($G$38="Fredag","t",IF($G$38="Lørdag","o",IF($G$38="Søndag","t","N/A"))))))) -> f | BC36: =IF($G$38="Mandag","l",IF($G$38="Tirsdag","s",IF($G$38="Onsdag","m",IF($G$38="Torsdag","t",IF($G$38="Fredag","o",IF($G$38="Lørdag","t",IF($G$38="Søndag","f","N/A"))))))) -> l | BD36: =IF($G$38="Mandag","s",IF($G$38="Tirsdag","m",IF($G$38="Onsdag","t",IF($G$38="Torsdag","o",IF($G$38="Fredag","t",IF($G$38="Lørdag","f",IF($G$38="Søndag","l","N/A"))))))) -> s | BE36: =IF($G$38="Mandag","m",IF($G$38="Tirsdag","t",IF($G$38="Onsdag","o",IF($G$38="Torsdag","t",IF($G$38="Fredag","f",IF($G$38="Lørdag","l",IF($G$38="Søndag","s","N/A"))))))) -> m | BF36: =IF($G$38="Mandag","t",IF($G$38="Tirsdag","o",IF($G$38="Onsdag","t",IF($G$38="Torsdag","f",IF($G$38="Fredag","l",IF($G$38="Lørdag","s",IF($G$38="Søndag","m","N/A"))))))) -> t | BG36: =IF($G$38="Mandag","o",IF($G$38="Tirsdag","t",IF($G$38="Onsdag","f",IF($G$38="Torsdag","l",IF($G$38="Fredag","s",IF($G$38="Lørdag","m",IF($G$38="Søndag","t","N/A"))))))) -> o | BH36: =IF($G$38="Mandag","t",IF($G$38="Tirsdag","f",IF($G$38="Onsdag","l",IF($G$38="Torsdag","s",IF($G$38="Fredag","m",IF($G$38="Lørdag","t",IF($G$38="Søndag","o","N/A"))))))) -> t | BI36: =IF($G$38="Mandag","f",IF($G$38="Tirsdag","l",IF($G$38="Onsdag","s",IF($G$38="Torsdag","m",IF($G$38="Fredag","t",IF($G$38="Lørdag","o",IF($G$38="Søndag","t","N/A"))))))) -> f | BJ36: =IF($G$38="Mandag","l",IF($G$38="Tirsdag","s",IF($G$38="Onsdag","m",IF($G$38="Torsdag","t",IF($G$38="Fredag","o",IF($G$38="Lørdag","t",IF($G$38="Søndag","f","N/A"))))))) -> l | BK36: =IF($G$38="Mandag","s",IF($G$38="Tirsdag","m",IF($G$38="Onsdag","t",IF($G$38="Torsdag","o",IF($G$38="Fredag","t",IF($G$38="Lørdag","f",IF($G$38="Søndag","l","N/A"))))))) -> s | BL36: =IF($G$38="Mandag","m",IF($G$38="Tirsdag","t",IF($G$38="Onsdag","o",IF($G$38="Torsdag","t",IF($G$38="Fredag","f",IF($G$38="Lørdag","l",IF($G$38="Søndag","s","N/A"))))))) -> m | BM36: =IF($G$38="Mandag","t",IF($G$38="Tirsdag","o",IF($G$38="Onsdag","t",IF($G$38="Torsdag","f",IF($G$38="Fredag","l",IF($G$38="Lørdag","s",IF($G$38="Søndag","m","N/A"))))))) -> t | BN36: =IF($G$38="Mandag","o",IF($G$38="Tirsdag","t",IF($G$38="Onsdag","f",IF($G$38="Torsdag","l",IF($G$38="Fredag","s",IF($G$38="Lørdag","m",IF($G$38="Søndag","t","N/A"))))))) -> o | BO36: =IF($G$38="Mandag","t",IF($G$38="Tirsdag","f",IF($G$38="Onsdag","l",IF($G$38="Torsdag","s",IF($G$38="Fredag","m",IF($G$38="Lørdag","t",IF($G$38="Søndag","o","N/A"))))))) -> t | BP36: =IF($G$38="Mandag","f",IF($G$38="Tirsdag","l",IF($G$38="Onsdag","s",IF($G$38="Torsdag","m",IF($G$38="Fredag","t",IF($G$38="Lørdag","o",IF($G$38="Søndag","t","N/A"))))))) -> f | BQ36: =IF($G$38="Mandag","l",IF($G$38="Tirsdag","s",IF($G$38="Onsdag","m",IF($G$38="Torsdag","t",IF($G$38="Fredag","o",IF($G$38="Lørdag","t",IF($G$38="Søndag","f","N/A"))))))) -> l | BR36: =IF($G$38="Mandag","s",IF($G$38="Tirsdag","m",IF($G$38="Onsdag","t",IF($G$38="Torsdag","o",IF($G$38="Fredag","t",IF($G$38="Lørdag","f",IF($G$38="Søndag","l","N/A"))))))) -> s | BS36: =IF($G$38="Mandag","m",IF($G$38="Tirsdag","t",IF($G$38="Onsdag","o",IF($G$38="Torsdag","t",IF($G$38="Fredag","f",IF($G$38="Lørdag","l",IF($G$38="Søndag","s","N/A"))))))) -> m | BT36: =IF($G$38="Mandag","t",IF($G$38="Tirsdag","o",IF($G$38="Onsdag","t",IF($G$38="Torsdag","f",IF($G$38="Fredag","l",IF($G$38="Lørdag","s",IF($G$38="Søndag","m","N/A"))))))) -> t | BU36: =IF($G$38="Mandag","o",IF($G$38="Tirsdag","t",IF($G$38="Onsdag","f",IF($G$38="Torsdag","l",IF($G$38="Fredag","s",IF($G$38="Lørdag","m",IF($G$38="Søndag","t","N/A"))))))) -> o | BV36: =IF($G$38="Mandag","t",IF($G$38="Tirsdag","f",IF($G$38="Onsdag","l",IF($G$38="Torsdag","s",IF($G$38="Fredag","m",IF($G$38="Lørdag","t",IF($G$38="Søndag","o","N/A"))))))) -> t | BW36: =IF($G$38="Mandag","f",IF($G$38="Tirsdag","l",IF($G$38="Onsdag","s",IF($G$38="Torsdag","m",IF($G$38="Fredag","t",IF($G$38="Lørdag","o",IF($G$38="Søndag","t","N/A"))))))) -> f | BX36: =IF($G$38="Mandag","l",IF($G$38="Tirsdag","s",IF($G$38="Onsdag","m",IF($G$38="Torsdag","t",IF($G$38="Fredag","o",IF($G$38="Lørdag","t",IF($G$38="Søndag","f","N/A"))))))) -> l | BY36: =IF($G$38="Mandag","s",IF($G$38="Tirsdag","m",IF($G$38="Onsdag","t",IF($G$38="Torsdag","o",IF($G$38="Fredag","t",IF($G$38="Lørdag","f",IF($G$38="Søndag","l","N/A"))))))) -> s | BZ36: =IF($G$38="Mandag","m",IF($G$38="Tirsdag","t",IF($G$38="Onsdag","o",IF($G$38="Torsdag","t",IF($G$38="Fredag","f",IF($G$38="Lørdag","l",IF($G$38="Søndag","s","N/A"))))))) -> m | CA36: =IF($G$38="Mandag","t",IF($G$38="Tirsdag","o",IF($G$38="Onsdag","t",IF($G$38="Torsdag","f",IF($G$38="Fredag","l",IF($G$38="Lørdag","s",IF($G$38="Søndag","m","N/A"))))))) -> t | CB36: =IF($G$38="Mandag","o",IF($G$38="Tirsdag","t",IF($G$38="Onsdag","f",IF($G$38="Torsdag","l",IF($G$38="Fredag","s",IF($G$38="Lørdag","m",IF($G$38="Søndag","t","N/A"))))))) -> o | CC36: =IF($G$38="Mandag","t",IF($G$38="Tirsdag","f",IF($G$38="Onsdag","l",IF($G$38="Torsdag","s",IF($G$38="Fredag","m",IF($G$38="Lørdag","t",IF($G$38="Søndag","o","N/A"))))))) -> t | CD36: =IF($G$38="Mandag","f",IF($G$38="Tirsdag","l",IF($G$38="Onsdag","s",IF($G$38="Torsdag","m",IF($G$38="Fredag","t",IF($G$38="Lørdag","o",IF($G$38="Søndag","t","N/A"))))))) -> f | CE36: =IF($G$38="Mandag","l",IF($G$38="Tirsdag","s",IF($G$38="Onsdag","m",IF($G$38="Torsdag","t",IF($G$38="Fredag","o",IF($G$38="Lørdag","t",IF($G$38="Søndag","f","N/A"))))))) -> l | CF36: =IF($G$38="Mandag","s",IF($G$38="Tirsdag","m",IF($G$38="Onsdag","t",IF($G$38="Torsdag","o",IF($G$38="Fredag","t",IF($G$38="Lørdag","f",IF($G$38="Søndag","l","N/A"))))))) -> s | CG36: Vakt lokasjon | CH36: Fra kl | CI36: Til kl | CJ36: Timer | CL36: =SUM(CL4:CL35) -> 123
A37: Ansatt fremstiller:
A38: Turnus Startdag | G38: mandag | L38: Sjekk for duplikater?
A39: Nr | B39: Navn | F39: uke 1 | H39: uke 2 | J39: uke 3 | L39: uke 4 | N39: uke 5 | P39: uke 6 | R39: Uke 7 | T39: Uke 8 | V39: Uke 9 | X39: Uke 10 | Z39: Uke 11 | AB39: Uke 12 | AD39: S UM | AG39: Uke snitt | AJ39: Uker i bruk | AM39: Stillingsprosent | AQ39: Uke Sats | AU39: Visning? | AX39: Regelbrudd? | BC39: Dette dokumentet kan sette opp vaktplaner og sjekke om de begår lovbrudd oppmot lov og avtale om arbeidstimer og hviletid.
A40: A | B40: test 1 | F40: ='Ansatt A'!$AK$6 -> 75 | H40: ='Ansatt A'!$AK$7 -> 0 | J40: ='Ansatt A'!$AK$8 -> 0 | L40: ='Ansatt A'!$AK$9 -> 0 | N40: ='Ansatt A'!$AK$10 -> 0 | P40: ='Ansatt A'!$AK$11 -> 0 | R40: ='Ansatt A'!$AK$12 -> 0 | T40: ='Ansatt A'!$AK$13 -> 0 | V40: ='Ansatt A'!$AK$14 -> 0 | X40: ='Ansatt A'!$AK$15 -> 0 | Z40: ='Ansatt A'!$AK$16 -> 0 | AB40: ='Ansatt A'!$AK$17 -> 0 | AD40: =F40+H40+J40+L40+N40+P40+R40+T40+V40+X40+Z40+AB40 -> 75 | AG40: =IFERROR(SUM(F40:AC40)/AJ40,0) -> 18.75 | AJ40: 4 | AM40: 1 | AU40: ja | AX40: =IF(OR('Ansatt A'!$B$45>0,'Ansatt A'!$B$67>0,'Ansatt A'!$B$70>0),"Ja","Nei") -> Ja | BC40: Jeg lagte denne selv for å hjelpe meg å tolke arbeidsplaner tilsendt fra arbeidsgiver som ofte hadde ulik utforming hver gang og ble da uoversiktelig.
...

Sheet Ansatt A
A1: Turnus start dag | E1: =Vaktplan!G38 -> mandag | H1: Antall uker i turnus 1-8 | M1: =Vaktplan!AJ40 -> 4
A2: Stillingsprosent | E2: =Vaktplan!AM40 -> 1
A3: Uke sats timer | E3: =Vaktplan!AQ40 -> 0 | F3: t/uke
A4: Uke | B4: =TEXT(AG39,"DDDD") -> Monday | G4: =TEXT($AG$39+1,"DDDD") -> Tuesday | L4: =TEXT($AG$39+2,"DDDD") -> Wednesday | Q4: =TEXT($AG$39+3,"DDDD") -> Thursday | V4: =TEXT($AG$39+4,"DDDD") -> Friday | AA4: =TEXT($AG$39+5,"DDDD") -> Saturday | AF4: =TEXT($AG$39+6,"DDDD") -> Sunday | AK4: Total ant. Timer
B5: Start | C5: slutt | D5: P | E5: Ant. Timer | F5: Hviletid | G5: Start | H5: slutt | I5: P | J5: Ant. Timer | K5: Hviletid | L5: Start | M5: slutt | N5: P | O5: Ant. Timer | P5: Hviletid | Q5: Start | R5: slutt | S5: P | T5: Ant. Timer | U5: Hviletid | V5: Start | W5: slutt | X5: P | Y5: Ant. Timer | Z5: Hviletid | AA5: Start | AB5: slutt | AC5: P | AD5: Ant. Timer | AE5: Hviletid | AF5: Start | AG5: slutt | AH5: P | AI5: Ant. Timer | AJ5: Hviletid
A6: =IF(M1>=1,1,0) -> 1 | B6: =IFERROR(VLOOKUP(Vaktplan!$A$40,Vaktplan!$A$4:$CL$35,87-AH59,FALSE),0) -> 0.29166667 | C6: =IFERROR(VLOOKUP(Vaktplan!$A$40,Vaktplan!$A$4:$CL$35,87-AG59,FALSE),0) -> 0.83333333 | D6: =IFERROR(VLOOKUP(Vaktplan!$A$40,Vaktplan!$A$4:$CL$35,89-AG59,FALSE),0) -> 0.5 | E6: =IF(AND(B6=0,C6=0),0,IF(B6<C6,((C6-B6)*24)-D6,(((1-B6)+C6)*24)-D6)) -> 12.5 | F6: =IF(AND(C6=0,G6=0),24,IF(C6=0,12+(G6*24),IF(C6<G6,((G6-C6)*24),IF(G6=0,(1-C6+0.5)*24,((1-C6)+G6)*24)))) -> 11 | G6: =IFERROR(VLOOKUP(Vaktplan!$A$40,Vaktplan!$B$4:$CL$35,86-AH59,FALSE),0) -> 0.29166667 | H6: =IFERROR(VLOOKUP(Vaktplan!$A$40,Vaktplan!$B$4:$CL$35,86-AG59,FALSE),0) -> 0.83333333 | I6: =IFERROR(VLOOKUP(Vaktplan!$A$40,Vaktplan!$B$4:$CL$35,89-$AH59,FALSE),0) -> 0.5 | J6: =IF(AND(G6=0,H6=0),0,IF(G6<H6,((H6-G6)*24)-I6,(((1-G6)+H6)*24)-I6)) -> 12.5 | K6: =IF(AND(H6=0,L6=0),24,IF(H6=0,12+(L6*24),IF(H6<L6,((L6-H6)*24),IF(L6=0,(1-H6+0.5)*24,((1-H6)+L6)*24)))) -> 11 | L6: =IFERROR(VLOOKUP(Vaktplan!$A$40,Vaktplan!$C$4:$CL$35,86-AI59,FALSE),0) -> 0.29166667 | M6: =IFERROR(VLOOKUP(Vaktplan!$A$40,Vaktplan!$C$4:$CL$35,86-AH59,FALSE),0) -> 0.83333333 | N6: =IFERROR(VLOOKUP(Vaktplan!$A$40,Vaktplan!$C$4:$CL$35,89-$AI59,FALSE),0) -> 0.5 | O6: =IF(AND(L6=0,M6=0),0,IF(L6<M6,((M6-L6)*24)-N6,(((1-L6)+M6)*24)-N6)) -> 12.5 | P6: =IF(AND(M6=0,Q6=0),24,IF(M6=0,12+(Q6*24),IF(M6<Q6,((Q6-M6)*24),IF(Q6=0,(1-M6+0.5)*24,((1-M6)+Q6)*24)))) -> 11 | Q6: =IFERROR(VLOOKUP(Vaktplan!$A$40,Vaktplan!$D$4:$CL$35,86-AJ59,FALSE),0) -> 0.29166667 | R6: =IFERROR(VLOOKUP(Vaktplan!$A$40,Vaktplan!$D$4:$CL$35,86-AI59,FALSE),0) -> 0.83333333 | S6: =IFERROR(VLOOKUP(Vaktplan!$A$40,Vaktplan!$D$4:$CL$35,89-$AJ59,FALSE),0) -> 0.5 | T6: =IF(AND(Q6=0,R6=0),0,IF(Q6<R6,((R6-Q6)*24)-S6,(((1-Q6)+R6)*24)-S6)) -> 12.5 | U6: =IF(AND(R6=0,V6=0),24,IF(R6=0,12+(V6*24),IF(R6<V6,((V6-R6)*24),IF(V6=0,(1-R6+0.5)*24,((1-R6)+V6)*24)))) -> 11 | V6: =IFERROR(VLOOKUP(Vaktplan!$A$40,Vaktplan!$E$4:$CL$35,86-AK59,FALSE),0) -> 0.29166667 | W6: =IFERROR(VLOOKUP(Vaktplan!$A$40,Vaktplan!$E$4:$CL$35,86-AJ59,FALSE),0) -> 0.83333333 | X6: =IFERROR(VLOOKUP(Vaktplan!$A$40,Vaktplan!$E$4:$CL$35,89-$AK59,FALSE),0) -> 0.5 | Y6: =IF(AND(V6=0,W6=0),0,IF(V6<W6,((W6-V6)*24)-X6,(((1-V6)+W6)*24)-X6)) -> 12.5 | Z6: =IF(AND(W6=0,AA6=0),24,IF(W6=0,12+(AA6*24),IF(W6<AA6,((AA6-W6)*24),IF(AA6=0,(1-W6+0.5)*24,((1-W6)+AA6)*24)))) -> 11 | AA6: =IFERROR(VLOOKUP(Vaktplan!$A$40,Vaktplan!$F$4:$CL$35,86-AL59,FALSE),0) -> 0.29166667 | AB6: =IFERROR(VLOOKUP(Vaktplan!$A$40,Vaktplan!$F$4:$CL$35,86-AK59,FALSE),0) -> 0.83333333 | AC6: =IFERROR(VLOOKUP(Vaktplan!$A$40,Vaktplan!$F$4:$CL$35,89-$AL59,FALSE),0) -> 0.5 | AD6: =IF(AND(AA6=0,AB6=0),0,IF(AA6<AB6,((AB6-AA6)*24)-AC6,(((1-AA6)+AB6)*24)-AC6)) -> 12.5 | AE6: =IF(AND(AB6=0,AF6=0),24,IF(AB6=0,12+(AF6*24),IF(AB6<AF6,((AF6-AB6)*24),IF(AF6=0,(1-AB6+0.5)*24,((1-AB6)+AF6)*24)))) -> 16 | AF6: =IFERROR(VLOOKUP(Vaktplan!$A$40,Vaktplan!$G$4:$CL$35,86-AM59,FALSE),0) -> 0 | AG6: =IFERROR(VLOOKUP(Vaktplan!$A$40,Vaktplan!$G$4:$CL$35,86-AL59,FALSE),0) -> 0 | AH6: =IFERROR(VLOOKUP(Vaktplan!$A$40,Vaktplan!$G$4:$CL$35,89-$AM59,FALSE),0) -> 0 | AI6: =IF(AND(AF6=0,AG6=0),0,IF(AF6<AG6,((AG6-AF6)*24)-AH6,(((1-AF6)+AG6)*24)-AH6)) -> 0 | AJ6: =IF($M$1=AL28,IF(AND(AG6=0,B6=0),24,IF(AG6=0,12+($B$6*24),IF(AG6<$B$6,(($B$6-AG6)*24),IF($B$6=0,(1-AG6+1)*24,((1-AG6)+$B$6)*24)))),IF(AND(AG6=0,B7=0),24,IF(AG6=0,12+(B7*24),IF(AG6<B7,((B7-AG6)*24),IF(B7=0,(1-AG6+1)*24,((1-AG6)+B7)*24))))) -> 24 | AK6: =E6+J6+O6+T6+Y6+AD6+AI6 -> 75 | AL6: =AJ6 -> 24 | AM6: =AK6 -> 75
A7: =IF($M$1>=2,2,0) -> 2 | B7: =IFERROR(VLOOKUP(Vaktplan!$A$40,Vaktplan!$H$4:$CL$35,87-AH60,FALSE),0) -> 0 | C7: =IFERROR(VLOOKUP(Vaktplan!$A$40,Vaktplan!$H$4:$CL$35,87-AG60,FALSE),0) -> 0 | D7: =IFERROR(VLOOKUP(Vaktplan!$A$40,Vaktplan!$H$4:$CL$35,89-AG60,FALSE),0) -> 0 | E7: =IF(AND(B7=0,C7=0),0,IF(B7<C7,((C7-B7)*24)-D7,(((1-B7)+C7)*24)-D7)) -> 0 | F7: =IF(AND(C7=0,G7=0),24,IF(C7=0,12+(G7*24),IF(C7<G7,((G7-C7)*24),IF(G7=0,(1-C7+0.5)*24,((1-C7)+G7)*24)))) -> 24 | G7: =IFERROR(VLOOKUP(Vaktplan!$A$40,Vaktplan!$I$4:$CL$35,86-AH60,FALSE),0) -> 0 | H7: =IFERROR(VLOOKUP(Vaktplan!$A$40,Vaktplan!$I$4:$CL$35,86-AG60,FALSE),0) -> 0 | I7: =IFERROR(VLOOKUP(Vaktplan!$A$40,Vaktplan!$I$4:$CL$35,89-$AH60,FALSE),0) -> 0 | J7: =IF(AND(G7=0,H7=0),0,IF(G7<H7,((H7-G7)*24)-I7,(((1-G7)+H7)*24)-I7)) -> 0 | K7: =IF(AND(H7=0,L7=0),24,IF(H7=0,12+(L7*24),IF(H7<L7,((L7-H7)*24),IF(L7=0,(1-H7+0.5)*24,((1-H7)+L7)*24)))) -> 24 | L7: =IFERROR(VLOOKUP(Vaktplan!$A$40,Vaktplan!$J$4:$CL$35,86-AI60,FALSE),0) -> 0 | M7: =IFERROR(VLOOKUP(Vaktplan!$A$40,Vaktplan!$J$4:$CL$35,86-AH60,FALSE),0) -> 0 | N7: =IFERROR(VLOOKUP(Vaktplan!$A$40,Vaktplan!$J$4:$CL$35,89-$AI60,FALSE),0) -> 0 | O7: =IF(AND(L7=0,M7=0),0,IF(L7<M7,((M7-L7)*24)-N7,(((1-L7)+M7)*24)-N7)) -> 0 | P7: =IF(AND(M7=0,Q7=0),24,IF(M7=0,12+(Q7*24),IF(M7<Q7,((Q7-M7)*24),IF(Q7=0,(1-M7+0.5)*24,((1-M7)+Q7)*24)))) -> 24 | Q7: =IFERROR(VLOOKUP(Vaktplan!$A$40,Vaktplan!$K$4:$CL$35,86-AJ60,FALSE),0) -> 0 | R7: =IFERROR(VLOOKUP(Vaktplan!$A$40,Vaktplan!$K$4:$CL$35,86-AI60,FALSE),0) -> 0 | S7: =IFERROR(VLOOKUP(Vaktplan!$A$40,Vaktplan!$K$4:$CL$35,89-$AJ60,FALSE),0) -> 0 | T7: =IF(AND(Q7=0,R7=0),0,IF(Q7<R7,((R7-Q7)*24)-S7,(((1-Q7)+R7)*24)-S7)) -> 0 | U7: =IF(AND(R7=0,V7=0),24,IF(R7=0,12+(V7*24),IF(R7<V7,((V7-R7)*24),IF(V7=0,(1-R7+0.5)*24,((1-R7)+V7)*24)))) -> 24 | V7: =IFERROR(VLOOKUP(Vaktplan!$A$40,Vaktplan!$L$4:$CL$35,86-AK60,FALSE),0) -> 0 | W7: =IFERROR(VLOOKUP(Vaktplan!$A$40,Vaktplan!$L$4:$CL$35,86-AJ60,FALSE),0) -> 0 | X7: =IFERROR(VLOOKUP(Vaktplan!$A$40,Vaktplan!$L$4:$CL$35,89-$AK60,FALSE),0) -> 0 | Y7: =IF(AND(V7=0,W7=0),0,IF(V7<W7,((W7-V7)*24)-X7,(((1-V7)+W7)*24)-X7)) -> 0 | Z7: =IF(AND(W7=0,AA7=0),24,IF(W7=0,12+(AA7*24),IF(W7<AA7,((AA7-W7)*24),IF(AA7=0,(1-W7+0.5)*24,((1-W7)+AA7)*24)))) -> 24 | AA7: =IFERROR(VLOOKUP(Vaktplan!$A$40,Vaktplan!$M$4:$CL$35,86-AL60,FALSE),0) -> 0 | AB7: =IFERROR(VLOOKUP(Vaktplan!$A$40,Vaktplan!$M$4:$CL$35,86-AK60,FALSE),0) -> 0 | AC7: =IFERROR(VLOOKUP(Vaktplan!$A$40,Vaktplan!$M$4:$CL$35,89-$AL60,FALSE),0) -> 0 | AD7: =IF(AND(AA7=0,AB7=0),0,IF(AA7<AB7,((AB7-AA7)*24)-AC7,(((1-AA7)+AB7)*24)-AC7)) -> 0 | AE7: =IF(AND(AB7=0,AF7=0),24,IF(AB7=0,12+(AF7*24),IF(AB7<AF7,((AF7-AB7)*24),IF(AF7=0,(1-AB7+0.5)*24,((1-AB7)+AF7)*24)))) -> 24 | AF7: =IFERROR(VLOOKUP(Vaktplan!$A$40,Vaktplan!$N$4:$CL$35,86-AM60,FALSE),0) -> 0 | AG7: =IFERROR(VLOOKUP(Vaktplan!$A$40,Vaktplan!$N$4:$CL$35,86-AL60,FALSE),0) -> 0 | AH7: =IFERROR(VLOOKUP(Vaktplan!$A$40,Vaktplan!$N$4:$CL$35,89-$AM60,FALSE),0) -> 0 | AI7: =IF(AND(AF7=0,AG7=0),0,IF(AF7<AG7,((AG7-AF7)*24)-AH7,(((1-AF7)+AG7)*24)-AH7)) -> 0 | AJ7: =IF($M$1=AL29,IF(AND(AG7=0,B7=0),24,IF(AG7=0,12+($B$6*24),IF(AG7<$B$6,(($B$6-AG7)*24),IF($B$6=0,(1-AG7+1)*24,((1-AG7)+$B$6)*24)))),IF(AND(AG7=0,B8=0),24,IF(AG7=0,12+(B8*24),IF(AG7<B8,((B8-AG7)*24),IF(B8=0,(1-AG7+1)*24,((1-AG7)+B8)*24))))) -> 24 | AK7: =E7+J7+O7+T7+Y7+AD7+AI7 -> 0 | AL7: =AJ7 -> 24 | AM7: =AK7 -> 0
A8: =IF($M$1>=3,3,0) -> 3 | B8: =IFERROR(VLOOKUP(Vaktplan!$A$40,Vaktplan!$O$4:$CL$35,87-AH61,FALSE),0) -> 0 | C8: =IFERROR(VLOOKUP(Vaktplan!$A$40,Vaktplan!$O$4:$CL$35,87-AG61,FALSE),0) -> 0 | D8: =IFERROR(VLOOKUP(Vaktplan!$A$40,Vaktplan!$O$4:$CL$35,89-AG61,FALSE),0) -> 0 | E8: =IF(AND(B8=0,C8=0),0,IF(B8<C8,((C8-B8)*24)-D8,(((1-B8)+C8)*24)-D8)) -> 0 | F8: =IF(AND(C8=0,G8=0),24,IF(C8=0,12+(G8*24),IF(C8<G8,((G8-C8)*24),IF(G8=0,(1-C8+0.5)*24,((1-C8)+G8)*24)))) -> 24 | G8: =IFERROR(VLOOKUP(Vaktplan!$A$40,Vaktplan!$P$4:$CL$35,86-AH61,FALSE),0) -> 0 | H8: =IFERROR(VLOOKUP(Vaktplan!$A$40,Vaktplan!$P$4:$CL$35,86-AG61,FALSE),0) -> 0 | I8: =IFERROR(VLOOKUP(Vaktplan!$A$40,Vaktplan!$P$4:$CL$35,89-$AH61,FALSE),0) -> 0 | J8: =IF(AND(G8=0,H8=0),0,IF(G8<H8,((H8-G8)*24)-I8,(((1-G8)+H8)*24)-I8)) -> 0 | K8: =IF(AND(H8=0,L8=0),24,IF(H8=0,12+(L8*24),IF(H8<L8,((L8-H8)*24),IF(L8=0,(1-H8+0.5)*24,((1-H8)+L8)*24)))) -> 24 | L8: =IFERROR(VLOOKUP(Vaktplan!$A$40,Vaktplan!$Q$4:$CL$35,86-AI61,FALSE),0) -> 0 | M8: =IFERROR(VLOOKUP(Vaktplan!$A$40,Vaktplan!$Q$4:$CL$35,86-AH61,FALSE),0) -> 0 | N8: =IFERROR(VLOOKUP(Vaktplan!$A$40,Vaktplan!$Q$4:$CL$35,89-$AI61,FALSE),0) -> 0 | O8: =IF(AND(L8=0,M8=0),0,IF(L8<M8,((M8-L8)*24)-N8,(((1-L8)+M8)*24)-N8)) -> 0 | P8: =IF(AND(M8=0,Q8=0),24,IF(M8=0,12+(Q8*24),IF(M8<Q8,((Q8-M8)*24),IF(Q8=0,(1-M8+0.5)*24,((1-M8)+Q8)*24)))) -> 24 | Q8: =IFERROR(VLOOKUP(Vaktplan!$A$40,Vaktplan!$R$4:$CL$35,86-AJ61,FALSE),0) -> 0 | R8: =IFERROR(VLOOKUP(Vaktplan!$A$40,Vaktplan!$R$4:$CL$35,86-AI61,FALSE),0) -> 0 | S8: =IFERROR(VLOOKUP(Vaktplan!$A$40,Vaktplan!$R$4:$CL$35,89-$AJ61,FALSE),0) -> 0 | T8: =IF(AND(Q8=0,R8=0),0,IF(Q8<R8,((R8-Q8)*24)-S8,(((1-Q8)+R8)*24)-S8)) -> 0 | U8: =IF(AND(R8=0,V8=0),24,IF(R8=0,12+(V8*24),IF(R8<V8,((V8-R8)*24),IF(V8=0,(1-R8+0.5)*24,((1-R8)+V8)*24)))) -> 24 | V8: =IFERROR(VLOOKUP(Vaktplan!$A$40,Vaktplan!$S$4:$CL$35,86-AK61,FALSE),0) -> 0 | W8: =IFERROR(VLOOKUP(Vaktplan!$A$40,Vaktplan!$S$4:$CL$35,86-AJ61,FALSE),0) -> 0 | X8: =IFERROR(VLOOKUP(Vaktplan!$A$40,Vaktplan!$S$4:$CL$35,89-$AK61,FALSE),0) -> 0 | Y8: =IF(AND(V8=0,W8=0),0,IF(V8<W8,((W8-V8)*24)-X8,(((1-V8)+W8)*24)-X8)) -> 0 | Z8: =IF(AND(W8=0,AA8=0),24,IF(W8=0,12+(AA8*24),IF(W8<AA8,((AA8-W8)*24),IF(AA8=0,(1-W8+0.5)*24,((1-W8)+AA8)*24)))) -> 24 | AA8: =IFERROR(VLOOKUP(Vaktplan!$A$40,Vaktplan!$T$4:$CL$35,86-AL61,FALSE),0) -> 0 | AB8: =IFERROR(VLOOKUP(Vaktplan!$A$40,Vaktplan!$T$4:$CL$35,86-AK61,FALSE),0) -> 0 | AC8: =IFERROR(VLOOKUP(Vaktplan!$A$40,Vaktplan!$T$4:$CL$35,89-$AL61,FALSE),0) -> 0 | AD8: =IF(AND(AA8=0,AB8=0),0,IF(AA8<AB8,((AB8-AA8)*24)-AC8,(((1-AA8)+AB8)*24)-AC8)) -> 0 | AE8: =IF(AND(AB8=0,AF8=0),24,IF(AB8=0,12+(AF8*24),IF(AB8<AF8,((AF8-AB8)*24),IF(AF8=0,(1-AB8+0.5)*24,((1-AB8)+AF8)*24)))) -> 24 | AF8: =IFERROR(VLOOKUP(Vaktplan!$A$40,Vaktplan!$U$4:$CL$35,86-AM61,FALSE),0) -> 0 | AG8: =IFERROR(VLOOKUP(Vaktplan!$A$40,Vaktplan!$U$4:$CL$35,86-AL61,FALSE),0) -> 0 | AH8: =IFERROR(VLOOKUP(Vaktplan!$A$40,Vaktplan!$U$4:$CL$35,89-$AM61,FALSE),0) -> 0 | AI8: =IF(AND(AF8=0,AG8=0),0,IF(AF8<AG8,((AG8-AF8)*24)-AH8,(((1-AF8)+AG8)*24)-AH8)) -> 0 | AJ8: =IF($M$1=AL30,IF(AND(AG8=0,B8=0),24,IF(AG8=0,12+($B$6*24),IF(AG8<$B$6,(($B$6-AG8)*24),IF($B$6=0,(1-AG8+1)*24,((1-AG8)+$B$6)*24)))),IF(AND(AG8=0,B9=0),24,IF(AG8=0,12+(B9*24),IF(AG8<B9,((B9-AG8)*24),IF(B9=0,(1-AG8+1)*24,((1-AG8)+B9)*24))))) -> 24 | AK8: =E8+J8+O8+T8+Y8+AD8+AI8 -> 0 | AL8: =AJ8 -> 24 | AM8: =AK8 -> 0
A9: =IF($M$1>=4,4,0) -> 4 | B9: =IFERROR(VLOOKUP(Vaktplan!$A$40,Vaktplan!$V$4:$CL$35,87-AH62,FALSE),0) -> 0 | C9: =IFERROR(VLOOKUP(Vaktplan!$A$40,Vaktplan!$V$4:$CL$35,87-AG62,FALSE),0) -> 0 | D9: =IFERROR(VLOOKUP(Vaktplan!$A$40,Vaktplan!$V$4:$CL$35,89-AG62,FALSE),0) -> 0 | E9: =IF(AND(B9=0,C9=0),0,IF(B9<C9,((C9-B9)*24)-D9,(((1-B9)+C9)*24)-D9)) -> 0 | F9: =IF(AND(C9=0,G9=0),24,IF(C9=0,12+(G9*24),IF(C9<G9,((G9-C9)*24),IF(G9=0,(1-C9+0.5)*24,((1-C9)+G9)*24)))) -> 24 | G9: =IFERROR(VLOOKUP(Vaktplan!$A$40,Vaktplan!$W$4:$CL$35,86-AH62,FALSE),0) -> 0 | H9: =IFERROR(VLOOKUP(Vaktplan!$A$40,Vaktplan!$W$4:$CL$35,86-AG62,FALSE),0) -> 0 | I9: =IFERROR(VLOOKUP(Vaktplan!$A$40,Vaktplan!$W$4:$CL$35,89-$AH62,FALSE),0) -> 0 | J9: =IF(AND(G9=0,H9=0),0,IF(G9<H9,((H9-G9)*24)-I9,(((1-G9)+H9)*24)-I9)) -> 0 | K9: =IF(AND(H9=0,L9=0),24,IF(H9=0,12+(L9*24),IF(H9<L9,((L9-H9)*24),IF(L9=0,(1-H9+0.5)*24,((1-H9)+L9)*24)))) -> 24 | L9: =IFERROR(VLOOKUP(Vaktplan!$A$40,Vaktplan!$X$4:$CL$35,86-AI62,FALSE),0) -> 0 | M9: =IFERROR(VLOOKUP(Vaktplan!$A$40,Vaktplan!$X$4:$CL$35,86-AH62,FALSE),0) -> 0 | N9: =IFERROR(VLOOKUP(Vaktplan!$A$40,Vaktplan!$X$4:$CL$35,89-$AI62,FALSE),0) -> 0 | O9: =IF(AND(L9=0,M9=0),0,IF(L9<M9,((M9-L9)*24)-N9,(((1-L9)+M9)*24)-N9)) -> 0 | P9: =IF(AND(M9=0,Q9=0),24,IF(M9=0,12+(Q9*24),IF(M9<Q9,((Q9-M9)*24),IF(Q9=0,(1-M9+0.5)*24,((1-M9)+Q9)*24)))) -> 24 | Q9: =IFERROR(VLOOKUP(Vaktplan!$A$40,Vaktplan!$Y$4:$CL$35,86-AJ62,FALSE),0) -> 0 | R9: =IFERROR(VLOOKUP(Vaktplan!$A$40,Vaktplan!$Y$4:$CL$35,86-AI62,FALSE),0) -> 0 | S9: =IFERROR(VLOOKUP(Vaktplan!$A$40,Vaktplan!$Y$4:$CL$35,89-$AJ62,FALSE),0) -> 0 | T9: =IF(AND(Q9=0,R9=0),0,IF(Q9<R9,((R9-Q9)*24)-S9,(((1-Q9)+R9)*24)-S9)) -> 0 | U9: =IF(AND(R9=0,V9=0),24,IF(R9=0,12+(V9*24),IF(R9<V9,((V9-R9)*24),IF(V9=0,(1-R9+0.5)*24,((1-R9)+V9)*24)))) -> 24 | V9: =IFERROR(VLOOKUP(Vaktplan!$A$40,Vaktplan!$Z$4:$CL$35,86-AK62,FALSE),0) -> 0 | W9: =IFERROR(VLOOKUP(Vaktplan!$A$40,Vaktplan!$Z$4:$CL$35,86-AJ62,FALSE),0) -> 0 | X9: =IFERROR(VLOOKUP(Vaktplan!$A$40,Vaktplan!$Z$4:$CL$35,89-$AK62,FALSE),0) -> 0 | Y9: =IF(AND(V9=0,W9=0),0,IF(V9<W9,((W9-V9)*24)-X9,(((1-V9)+W9)*24)-X9)) -> 0 | Z9: =IF(AND(W9=0,AA9=0),24,IF(W9=0,12+(AA9*24),IF(W9<AA9,((AA9-W9)*24),IF(AA9=0,(1-W9+0.5)*24,((1-W9)+AA9)*24)))) -> 24 | AA9: =IFERROR(VLOOKUP(Vaktplan!$A$40,Vaktplan!$AA$4:$CL$35,86-AL62,FALSE),0) -> 0 | AB9: =IFERROR(VLOOKUP(Vaktplan!$A$40,Vaktplan!$AA$4:$CL$35,86-AK62,FALSE),0) -> 0 | AC9: =IFERROR(VLOOKUP(Vaktplan!$A$40,Vaktplan!$AA$4:$CL$35,89-$AL62,FALSE),0) -> 0 | AD9: =IF(AND(AA9=0,AB9=0),0,IF(AA9<AB9,((AB9-AA9)*24)-AC9,(((1-AA9)+AB9)*24)-AC9)) -> 0 | AE9: =IF(AND(AB9=0,AF9=0),24,IF(AB9=0,12+(AF9*24),IF(AB9<AF9,((AF9-AB9)*24),IF(AF9=0,(1-AB9+0.5)*24,((1-AB9)+AF9)*24)))) -> 24 | AF9: =IFERROR(VLOOKUP(Vaktplan!$A$40,Vaktplan!$AB$4:$CL$35,86-AM62,FALSE),0) -> 0 | AG9: =IFERROR(VLOOKUP(Vaktplan!$A$40,Vaktplan!$AB$4:$CL$35,86-AL62,FALSE),0) -> 0 | AH9: =IFERROR(VLOOKUP(Vaktplan!$A$40,Vaktplan!$AB$4:$CL$35,89-$AM62,FALSE),0) -> 0 | AI9: =IF(AND(AF9=0,AG9=0),0,IF(AF9<AG9,((AG9-AF9)*24)-AH9,(((1-AF9)+AG9)*24)-AH9)) -> 0 | AJ9: =IF($M$1=AL31,IF(AND(AG9=0,B9=0),24,IF(AG9=0,12+($B$6*24),IF(AG9<$B$6,(($B$6-AG9)*24),IF($B$6=0,(1-AG9+1)*24,((1-AG9)+$B$6)*24)))),IF(AND(AG9=0,B10=0),24,IF(AG9=0,12+(B10*24),IF(AG9<B10,((B10-AG9)*24),IF(B10=0,(1-AG9+1)*24,((1-AG9)+B10)*24))))) -> 24 | AK9: =E9+J9+O9+T9+Y9+AD9+AI9 -> 0 | AL9: =AJ9 -> 24 | AM9: =AK9 -> 0
A10: =IF($M$1>=5,5,0) -> 0 | B10: =IFERROR(VLOOKUP(Vaktplan!$A$40,Vaktplan!$AC$4:$CL$35,87-AH63,FALSE),0) -> 0 | C10: =IFERROR(VLOOKUP(Vaktplan!$A$40,Vaktplan!$AC$4:$CL$35,87-AG63,FALSE),0) -> 0 | D10: =IFERROR(VLOOKUP(Vaktplan!$A$40,Vaktplan!$AC$4:$CL$35,89-AG63,FALSE),0) -> 0 | E10: =IF(AND(B10=0,C10=0),0,IF(B10<C10,((C10-B10)*24)-D10,(((1-B10)+C10)*24)-D10)) -> 0 | F10: =IF(AND(C10=0,G10=0),24,IF(C10=0,12+(G10*24),IF(C10<G10,((G10-C10)*24),IF(G10=0,(1-C10+0.5)*24,((1-C10)+G10)*24)))) -> 24 | G10: =IFERROR(VLOOKUP(Vaktplan!$A$40,Vaktplan!$AD$4:$CL$35,86-AH63,FALSE),0) -> 0 | H10: =IFERROR(VLOOKUP(Vaktplan!$A$40,Vaktplan!$AD$4:$CL$35,86-AG63,FALSE),0) -> 0 | I10: =IFERROR(VLOOKUP(Vaktplan!$A$40,Vaktplan!$AD$4:$CL$35,89-$AH63,FALSE),0) -> 0 | J10: =IF(AND(G10=0,H10=0),0,IF(G10<H10,((H10-G10)*24)-I10,(((1-G10)+H10)*24)-I10)) -> 0 | K10: =IF(AND(H10=0,L10=0),24,IF(H10=0,12+(L10*24),IF(H10<L10,((L10-H10)*24),IF(L10=0,(1-H10+0.5)*24,((1-H10)+L10)*24)))) -> 24 | L10: =IFERROR(VLOOKUP(Vaktplan!$A$40,Vaktplan!$AE$4:$CL$35,86-AI63,FALSE),0) -> 0 | M10: =IFERROR(VLOOKUP(Vaktplan!$A$40,Vaktplan!$AE$4:$CL$35,86-AH63,FALSE),0) -> 0 | N10: =IFERROR(VLOOKUP(Vaktplan!$A$40,Vaktplan!$AE$4:$CL$35,89-$AI63,FALSE),0) -> 0 | O10: =IF(AND(L10=0,M10=0),0,IF(L10<M10,((M10-L10)*24)-N10,(((1-L10)+M10)*24)-N10)) -> 0 | P10: =IF(AND(M10=0,Q10=0),24,IF(M10=0,12+(Q10*24),IF(M10<Q10,((Q10-M10)*24),IF(Q10=0,(1-M10+0.5)*24,((1-M10)+Q10)*24)))) -> 24 | Q10: =IFERROR(VLOOKUP(Vaktplan!$A$40,Vaktplan!$AF$4:$CL$35,86-AJ63,FALSE),0) -> 0 | R10: =IFERROR(VLOOKUP(Vaktplan!$A$40,Vaktplan!$AF$4:$CL$35,86-AI63,FALSE),0) -> 0 | S10: =IFERROR(VLOOKUP(Vaktplan!$A$40,Vaktplan!$AF$4:$CL$35,89-$AJ63,FALSE),0) -> 0 | T10: =IF(AND(Q10=0,R10=0),0,IF(Q10<R10,((R10-Q10)*24)-S10,(((1-Q10)+R10)*24)-S10)) -> 0 | U10: =IF(AND(R10=0,V10=0),24,IF(R10=0,12+(V10*24),IF(R10<V10,((V10-R10)*24),IF(V10=0,(1-R10+0.5)*24,((1-R10)+V10)*24)))) -> 24 | V10: =IFERROR(VLOOKUP(Vaktplan!$A$40,Vaktplan!$AG$4:$CL$35,86-AK63,FALSE),0) -> 0 | W10: =IFERROR(VLOOKUP(Vaktplan!$A$40,Vaktplan!$AG$4:$CL$35,86-AJ63,FALSE),0) -> 0 | X10: =IFERROR(VLOOKUP(Vaktplan!$A$40,Vaktplan!$AG$4:$CL$35,89-$AK63,FALSE),0) -> 0 | Y10: =IF(AND(V10=0,W10=0),0,IF(V10<W10,((W10-V10)*24)-X10,(((1-V10)+W10)*24)-X10)) -> 0 | Z10: =IF(AND(W10=0,AA10=0),24,IF(W10=0,12+(AA10*24),IF(W10<AA10,((AA10-W10)*24),IF(AA10=0,(1-W10+0.5)*24,((1-W10)+AA10)*24)))) -> 24 | AA10: =IFERROR(VLOOKUP(Vaktplan!$A$40,Vaktplan!$AH$4:$CL$35,86-AL63,FALSE),0) -> 0 | AB10: =IFERROR(VLOOKUP(Vaktplan!$A$40,Vaktplan!$AH$4:$CL$35,86-AK63,FALSE),0) -> 0 | AC10: =IFERROR(VLOOKUP(Vaktplan!$A$40,Vaktplan!$AH$4:$CL$35,89-$AL63,FALSE),0) -> 0 | AD10: =IF(AND(AA10=0,AB10=0),0,IF(AA10<AB10,((AB10-AA10)*24)-AC10,(((1-AA10)+AB10)*24)-AC10)) -> 0 | AE10: =IF(AND(AB10=0,AF10=0),24,IF(AB10=0,12+(AF10*24),IF(AB10<AF10,((AF10-AB10)*24),IF(AF10=0,(1-AB10+0.5)*24,((1-AB10)+AF10)*24)))) -> 24 | AF10: =IFERROR(VLOOKUP(Vaktplan!$A$40,Vaktplan!$AI$4:$CL$35,86-AM63,FALSE),0) -> 0 | AG10: =IFERROR(VLOOKUP(Vaktplan!$A$40,Vaktplan!$AI$4:$CL$35,86-AL63,FALSE),0) -> 0 | AH10: =IFERROR(VLOOKUP(Vaktplan!$A$40,Vaktplan!$AI$4:$CL$35,89-$AM63,FALSE),0) -> 0 | AI10: =IF(AND(AF10=0,AG10=0),0,IF(AF10<AG10,((AG10-AF10)*24)-AH10,(((1-AF10)+AG10)*24)-AH10)) -> 0 | AJ10: =IF($M$1=AL32,IF(AND(AG10=0,B10=0),24,IF(AG10=0,12+($B$6*24),IF(AG10<$B$6,(($B$6-AG10)*24),IF($B$6=0,(1-AG10+1)*24,((1-AG10)+$B$6)*24)))),IF(AND(AG10=0,B11=0),24,IF(AG10=0,12+(B11*24),IF(AG10<B11,((B11-AG10)*24),IF(B11=0,(1-AG10+1)*24,((1-AG10)+B11)*24))))) -> 24 | AK10: =E10+J10+O10+T10+Y10+AD10+AI10 -> 0 | AL10: =AJ10 -> 24 | AM10: =AK10 -> 0
A11: =IF($M$1>=6,6,0) -> 0 | B11: =IFERROR(VLOOKUP(Vaktplan!$A$40,Vaktplan!$AJ$4:$CL$35,87-AH64,FALSE),0) -> 0 | C11: =IFERROR(VLOOKUP(Vaktplan!$A$40,Vaktplan!$AJ$4:$CL$35,87-AG64,FALSE),0) -> 0 | D11: =IFERROR(VLOOKUP(Vaktplan!$A$40,Vaktplan!$AJ$4:$CL$35,89-AG64,FALSE),0) -> 0 | E11: =IF(AND(B11=0,C11=0),0,IF(B11<C11,((C11-B11)*24)-D11,(((1-B11)+C11)*24)-D11)) -> 0 | F11: =IF(AND(C11=0,G11=0),24,IF(C11=0,12+(G11*24),IF(C11<G11,((G11-C11)*24),IF(G11=0,(1-C11+0.5)*24,((1-C11)+G11)*24)))) -> 24 | G11: =IFERROR(VLOOKUP(Vaktplan!$A$40,Vaktplan!$AK$4:$CL$35,86-AH64,FALSE),0) -> 0 | H11: =IFERROR(VLOOKUP(Vaktplan!$A$40,Vaktplan!$AK$4:$CL$35,86-AG64,FALSE),0) -> 0 | I11: =IFERROR(VLOOKUP(Vaktplan!$A$40,Vaktplan!$AK$4:$CL$35,89-$AH64,FALSE),0) -> 0 | J11: =IF(AND(G11=0,H11=0),0,IF(G11<H11,((H11-G11)*24)-I11,(((1-G11)+H11)*24)-I11)) -> 0 | K11: =IF(AND(H11=0,L11=0),24,IF(H11=0,12+(L11*24),IF(H11<L11,((L11-H11)*24),IF(L11=0,(1-H11+0.5)*24,((1-H11)+L11)*24)))) -> 24 | L11: =IFERROR(VLOOKUP(Vaktplan!$A$40,Vaktplan!$AL$4:$CL$35,86-AI64,FALSE),0) -> 0 | M11: =IFERROR(VLOOKUP(Vaktplan!$A$40,Vaktplan!$AL$4:$CL$35,86-AH64,FALSE),0) -> 0 | N11: =IFERROR(VLOOKUP(Vaktplan!$A$40,Vaktplan!$AL$4:$CL$35,89-$AI64,FALSE),0) -> 0 | O11: =IF(AND(L11=0,M11=0),0,IF(L11<M11,((M11-L11)*24)-N11,(((1-L11)+M11)*24)-N11)) -> 0 | P11: =IF(AND(M11=0,Q11=0),24,IF(M11=0,12+(Q11*24),IF(M11<Q11,((Q11-M11)*24),IF(Q11=0,(1-M11+0.5)*24,((1-M11)+Q11)*24)))) -> 24 | Q11: =IFERROR(VLOOKUP(Vaktplan!$A$40,Vaktplan!$AM$4:$CL$35,86-AJ64,FALSE),0) -> 0 | R11: =IFERROR(VLOOKUP(Vaktplan!$A$40,Vaktplan!$AM$4:$CL$35,86-AI64,FALSE),0) -> 0 | S11: =IFERROR(VLOOKUP(Vaktplan!$A$40,Vaktplan!$AM$4:$CL$35,89-$AJ64,FALSE),0) -> 0 | T11: =IF(AND(Q11=0,R11=0),0,IF(Q11<R11,((R11-Q11)*24)-S11,(((1-Q11)+R11)*24)-S11)) -> 0 | U11: =IF(AND(R11=0,V11=0),24,IF(R11=0,12+(V11*24),IF(R11<V11,((V11-R11)*24),IF(V11=0,(1-R11+0.5)*24,((1-R11)+V11)*24)))) -> 24 | V11: =IFERROR(VLOOKUP(Vaktplan!$A$40,Vaktplan!$AN$4:$CL$35,86-AK64,FALSE),0) -> 0 | W11: =IFERROR(VLOOKUP(Vaktplan!$A$40,Vaktplan!$AN$4:$CL$35,86-AJ64,FALSE),0) -> 0 | X11: =IFERROR(VLOOKUP(Vaktplan!$A$40,Vaktplan!$AN$4:$CL$35,89-$AK64,FALSE),0) -> 0 | Y11: =IF(AND(V11=0,W11=0),0,IF(V11<W11,((W11-V11)*24)-X11,(((1-V11)+W11)*24)-X11)) -> 0 | Z11: =IF(AND(W11=0,AA11=0),24,IF(W11=0,12+(AA11*24),IF(W11<AA11,((AA11-W11)*24),IF(AA11=0,(1-W11+0.5)*24,((1-W11)+AA11)*24)))) -> 24 | AA11: =IFERROR(VLOOKUP(Vaktplan!$A$40,Vaktplan!$AO$4:$CL$35,86-AL64,FALSE),0) -> 0 | AB11: =IFERROR(VLOOKUP(Vaktplan!$A$40,Vaktplan!$AO$4:$CL$35,86-AK64,FALSE),0) -> 0 | AC11: =IFERROR(VLOOKUP(Vaktplan!$A$40,Vaktplan!$AO$4:$CL$35,89-$AL64,FALSE),0) -> 0 | AD11: =IF(AND(AA11=0,AB11=0),0,IF(AA11<AB11,((AB11-AA11)*24)-AC11,(((1-AA11)+AB11)*24)-AC11)) -> 0 | AE11: =IF(AND(AB11=0,AF11=0),24,IF(AB11=0,12+(AF11*24),IF(AB11<AF11,((AF11-AB11)*24),IF(AF11=0,(1-AB11+0.5)*24,((1-AB11)+AF11)*24)))) -> 24 | AF11: =IFERROR(VLOOKUP(Vaktplan!$A$40,Vaktplan!$AP$4:$CL$35,86-AM64,FALSE),0) -> 0 | AG11: =IFERROR(VLOOKUP(Vaktplan!$A$40,Vaktplan!$AP$4:$CL$35,86-AL64,FALSE),0) -> 0 | AH11: =IFERROR(VLOOKUP(Vaktplan!$A$40,Vaktplan!$AP$4:$CL$35,89-$AM64,FALSE),0) -> 0 | AI11: =IF(AND(AF11=0,AG11=0),0,IF(AF11<AG11,((AG11-AF11)*24)-AH11,(((1-AF11)+AG11)*24)-AH11)) -> 0 | AJ11: =IF($M$1=AL33,IF(AND(AG11=0,B11=0),24,IF(AG11=0,12+($B$6*24),IF(AG11<$B$6,(($B$6-AG11)*24),IF($B$6=0,(1-AG11+1)*24,((1-AG11)+$B$6)*24)))),IF(AND(AG11=0,B12=0),24,IF(AG11=0,12+(B12*24),IF(AG11<B12,((B12-AG11)*24),IF(B12=0,(1-AG11+1)*24,((1-AG11)+B12)*24))))) -> 24 | AK11: =E11+J11+O11+T11+Y11+AD11+AI11 -> 0 | AL11: =AJ11 -> 24 | AM11: =AK11 -> 0
